WARNING 2018-09-19 11:24:50,906 base 152 Not Found: /
WARNING 2018-09-19 11:24:50,910 basehttp 124 "GET / HTTP/1.1" 404 2101
INFO 2018-09-19 11:25:19,028 basehttp 124 "GET /sms_codes/15170444038/ HTTP/1.1" 200 5176
INFO 2018-09-19 11:25:19,057 basehttp 124 "GET /static/rest_framework/css/bootstrap.min.css HTTP/1.1" 200 121200
INFO 2018-09-19 11:25:19,062 basehttp 124 "GET /static/rest_framework/css/bootstrap-tweaks.css HTTP/1.1" 200 3385
INFO 2018-09-19 11:25:19,063 basehttp 124 "GET /static/rest_framework/css/default.css HTTP/1.1" 200 1131
INFO 2018-09-19 11:25:19,068 basehttp 124 "GET /static/rest_framework/css/prettify.css HTTP/1.1" 200 817
INFO 2018-09-19 11:25:19,069 basehttp 124 "GET /static/rest_framework/js/jquery-3.3.1.min.js HTTP/1.1" 200 86927
INFO 2018-09-19 11:25:19,082 basehttp 124 "GET /static/rest_framework/js/csrf.js HTTP/1.1" 200 1735
INFO 2018-09-19 11:25:19,091 basehttp 124 "GET /static/rest_framework/js/ajax-form.js HTTP/1.1" 200 3597
INFO 2018-09-19 11:25:19,097 basehttp 124 "GET /static/rest_framework/js/bootstrap.min.js HTTP/1.1" 200 37045
INFO 2018-09-19 11:25:19,098 basehttp 124 "GET /static/rest_framework/js/prettify-min.js HTTP/1.1" 200 13632
INFO 2018-09-19 11:25:19,099 basehttp 124 "GET /static/rest_framework/js/default.js HTTP/1.1" 200 1262
INFO 2018-09-19 11:25:19,103 basehttp 124 "GET /static/rest_framework/img/grid.png HTTP/1.1" 200 1458
WARNING 2018-09-19 11:29:40,093 base 152 Not Found: /oauth/qq/authorization/
WARNING 2018-09-19 11:29:40,094 basehttp 124 "GET /oauth/qq/authorization/?state=/ HTTP/1.1" 404 2202
WARNING 2018-09-19 11:29:52,738 base 152 Not Found: /mobiles/15170444038/count/
WARNING 2018-09-19 11:29:52,738 basehttp 124 "GET /mobiles/15170444038/count/ HTTP/1.1" 404 2203
WARNING 2018-09-19 11:29:52,878 base 152 Not Found: /mobiles/15170444038/count/
WARNING 2018-09-19 11:29:52,878 basehttp 124 "GET /mobiles/15170444038/count/ HTTP/1.1" 404 2203
WARNING 2018-09-19 12:34:32,800 base 152 Not Found: /mobiles/15170444038/count/
WARNING 2018-09-19 12:34:32,801 basehttp 124 "GET /mobiles/15170444038/count/ HTTP/1.1" 404 2203
WARNING 2018-09-19 12:34:32,947 base 152 Not Found: /mobiles/15170444038/count/
WARNING 2018-09-19 12:34:32,952 basehttp 124 "GET /mobiles/15170444038/count/ HTTP/1.1" 404 2203
WARNING 2018-09-19 12:35:14,982 tasks 30 发送验证码短信[失败][ mobile: 15170444038 ]
INFO 2018-09-19 12:35:14,984 basehttp 124 "GET /sms_codes/15170444038/ HTTP/1.1" 200 16
WARNING 2018-09-19 12:49:48,296 base 152 Not Found: /mobiles/15170444038/count/
WARNING 2018-09-19 12:49:48,297 basehttp 124 "GET /mobiles/15170444038/count/ HTTP/1.1" 404 2203
WARNING 2018-09-19 12:49:48,434 base 152 Not Found: /mobiles/15170444038/count/
WARNING 2018-09-19 12:49:48,439 basehttp 124 "GET /mobiles/15170444038/count/ HTTP/1.1" 404 2203
WARNING 2018-09-19 12:50:09,459 tasks 30 发送验证码短信[失败][ mobile: 15170444038 ]
INFO 2018-09-19 12:50:09,460 basehttp 124 "GET /sms_codes/15170444038/ HTTP/1.1" 200 16
WARNING 2018-09-19 12:52:08,692 tasks 30 发送验证码短信[失败][ mobile: 15170444038 ]
INFO 2018-09-19 12:52:08,717 basehttp 124 "GET /sms_codes/15170444038/ HTTP/1.1" 200 5176
INFO 2018-09-19 12:52:08,748 basehttp 124 "GET /static/rest_framework/css/bootstrap.min.css HTTP/1.1" 304 0
INFO 2018-09-19 12:52:08,756 basehttp 124 "GET /static/rest_framework/css/bootstrap-tweaks.css HTTP/1.1" 304 0
INFO 2018-09-19 12:52:08,760 basehttp 124 "GET /static/rest_framework/css/prettify.css HTTP/1.1" 304 0
INFO 2018-09-19 12:52:08,762 basehttp 124 "GET /static/rest_framework/css/default.css HTTP/1.1" 304 0
INFO 2018-09-19 12:52:08,769 basehttp 124 "GET /static/rest_framework/js/jquery-3.3.1.min.js HTTP/1.1" 304 0
INFO 2018-09-19 12:52:08,771 basehttp 124 "GET /static/rest_framework/js/ajax-form.js HTTP/1.1" 304 0
INFO 2018-09-19 12:52:08,777 basehttp 124 "GET /static/rest_framework/js/csrf.js HTTP/1.1" 304 0
INFO 2018-09-19 12:52:08,780 basehttp 124 "GET /static/rest_framework/js/bootstrap.min.js HTTP/1.1" 304 0
INFO 2018-09-19 12:52:08,784 basehttp 124 "GET /static/rest_framework/js/default.js HTTP/1.1" 304 0
INFO 2018-09-19 12:52:08,786 basehttp 124 "GET /static/rest_framework/js/prettify-min.js HTTP/1.1" 304 0
INFO 2018-09-19 12:52:08,792 basehttp 124 "GET /static/rest_framework/img/grid.png HTTP/1.1" 304 0
WARNING 2018-09-19 12:52:37,084 tasks 30 发送验证码短信[失败][ mobile: 15170444038 ]
INFO 2018-09-19 12:52:37,095 basehttp 124 "GET /sms_codes/15170444038/ HTTP/1.1" 200 5176
INFO 2018-09-19 13:00:26,506 basehttp 124 "GET /mobiles/15170444038/count/ HTTP/1.1" 200 34
INFO 2018-09-19 13:00:26,663 basehttp 124 "GET /mobiles/15170444038/count/ HTTP/1.1" 200 34
WARNING 2018-09-19 13:00:47,688 tasks 30 发送验证码短信[失败][ mobile: 15170444038 ]
INFO 2018-09-19 13:00:47,689 basehttp 124 "GET /sms_codes/15170444038/ HTTP/1.1" 200 16
INFO 2018-09-19 15:08:02,028 basehttp 124 "GET /usernames/15170444038/count/ HTTP/1.1" 200 36
INFO 2018-09-19 15:08:24,206 basehttp 124 "GET /mobiles/15170444038/count/ HTTP/1.1" 200 34
INFO 2018-09-19 15:08:25,398 basehttp 124 "GET /mobiles/15170444038/count/ HTTP/1.1" 200 34
INFO 2018-09-19 15:08:39,525 basehttp 124 "GET /mobiles/15170444038/count/ HTTP/1.1" 200 34
INFO 2018-09-19 15:08:41,971 basehttp 124 "GET /mobiles/15170444038/count/ HTTP/1.1" 200 34
INFO 2018-09-19 15:08:43,923 basehttp 124 "GET /mobiles/15170444038/count/ HTTP/1.1" 200 34
WARNING 2018-09-19 15:08:46,446 tasks 30 发送验证码短信[失败][ mobile: 15170444038 ]
INFO 2018-09-19 15:08:46,448 basehttp 124 "GET /sms_codes/15170444038/ HTTP/1.1" 200 16
INFO 2018-09-19 15:09:00,730 basehttp 124 "OPTIONS /users/ HTTP/1.1" 200 0
WARNING 2018-09-19 15:09:00,736 base 152 Not Found: /users/
WARNING 2018-09-19 15:09:00,737 basehttp 124 "POST /users/ HTTP/1.1" 404 2688
INFO 2018-09-19 15:09:00,748 basehttp 124 "GET /usernames/15170444038/count/ HTTP/1.1" 200 36
INFO 2018-09-19 15:09:00,749 basehttp 124 "GET /mobiles/15170444038/count/ HTTP/1.1" 200 34
WARNING 2018-09-19 15:09:16,219 base 152 Not Found: /users/
WARNING 2018-09-19 15:09:16,222 basehttp 124 "POST /users/ HTTP/1.1" 404 2688
INFO 2018-09-19 15:09:16,270 basehttp 124 "GET /usernames/15170444038/count/ HTTP/1.1" 200 36
INFO 2018-09-19 15:09:16,272 basehttp 124 "GET /mobiles/15170444038/count/ HTTP/1.1" 200 34
WARNING 2018-09-19 15:09:17,034 base 152 Not Found: /users/
WARNING 2018-09-19 15:09:17,036 basehttp 124 "POST /users/ HTTP/1.1" 404 2688
INFO 2018-09-19 15:09:17,043 basehttp 124 "GET /mobiles/15170444038/count/ HTTP/1.1" 200 34
INFO 2018-09-19 15:09:17,045 basehttp 124 "GET /usernames/15170444038/count/ HTTP/1.1" 200 36
WARNING 2018-09-19 15:09:17,286 base 152 Not Found: /users/
WARNING 2018-09-19 15:09:17,288 basehttp 124 "POST /users/ HTTP/1.1" 404 2688
INFO 2018-09-19 15:09:17,296 basehttp 124 "GET /usernames/15170444038/count/ HTTP/1.1" 200 36
INFO 2018-09-19 15:09:17,299 basehttp 124 "GET /mobiles/15170444038/count/ HTTP/1.1" 200 34
WARNING 2018-09-19 15:09:17,496 base 152 Not Found: /users/
WARNING 2018-09-19 15:09:17,498 basehttp 124 "POST /users/ HTTP/1.1" 404 2688
INFO 2018-09-19 15:09:17,501 basehttp 124 "GET /usernames/15170444038/count/ HTTP/1.1" 200 36
INFO 2018-09-19 15:09:17,504 basehttp 124 "GET /mobiles/15170444038/count/ HTTP/1.1" 200 34
WARNING 2018-09-19 15:09:17,646 base 152 Not Found: /users/
WARNING 2018-09-19 15:09:17,649 basehttp 124 "POST /users/ HTTP/1.1" 404 2688
INFO 2018-09-19 15:09:17,657 basehttp 124 "GET /usernames/15170444038/count/ HTTP/1.1" 200 36
INFO 2018-09-19 15:09:17,660 basehttp 124 "GET /mobiles/15170444038/count/ HTTP/1.1" 200 34
WARNING 2018-09-19 15:09:17,828 base 152 Not Found: /users/
WARNING 2018-09-19 15:09:17,834 basehttp 124 "POST /users/ HTTP/1.1" 404 2688
INFO 2018-09-19 15:09:17,841 basehttp 124 "GET /usernames/15170444038/count/ HTTP/1.1" 200 36
INFO 2018-09-19 15:09:17,843 basehttp 124 "GET /mobiles/15170444038/count/ HTTP/1.1" 200 34
WARNING 2018-09-19 15:09:18,001 base 152 Not Found: /users/
WARNING 2018-09-19 15:09:18,003 basehttp 124 "POST /users/ HTTP/1.1" 404 2688
INFO 2018-09-19 15:09:18,011 basehttp 124 "GET /usernames/15170444038/count/ HTTP/1.1" 200 36
INFO 2018-09-19 15:09:18,012 basehttp 124 "GET /mobiles/15170444038/count/ HTTP/1.1" 200 34
WARNING 2018-09-19 15:09:18,199 base 152 Not Found: /users/
WARNING 2018-09-19 15:09:18,203 basehttp 124 "POST /users/ HTTP/1.1" 404 2688
INFO 2018-09-19 15:09:18,209 basehttp 124 "GET /usernames/15170444038/count/ HTTP/1.1" 200 36
INFO 2018-09-19 15:09:18,214 basehttp 124 "GET /mobiles/15170444038/count/ HTTP/1.1" 200 34
WARNING 2018-09-19 15:09:19,748 base 152 Not Found: /users/
WARNING 2018-09-19 15:09:19,751 basehttp 124 "POST /users/ HTTP/1.1" 404 2688
INFO 2018-09-19 15:09:19,756 basehttp 124 "GET /usernames/15170444038/count/ HTTP/1.1" 200 36
INFO 2018-09-19 15:09:19,759 basehttp 124 "GET /mobiles/15170444038/count/ HTTP/1.1" 200 34
WARNING 2018-09-19 15:09:21,404 base 152 Not Found: /users/
WARNING 2018-09-19 15:09:21,406 basehttp 124 "POST /users/ HTTP/1.1" 404 2688
INFO 2018-09-19 15:09:21,413 basehttp 124 "GET /mobiles/15170444038/count/ HTTP/1.1" 200 34
INFO 2018-09-19 15:09:21,417 basehttp 124 "GET /usernames/15170444038/count/ HTTP/1.1" 200 36
ERROR 2018-09-19 15:09:46,428 exception 135 Internal Server Error: /users/
Traceback (most recent call last):
  File "/home/python/.virtualenvs/django-py3-1.11/lib/python3.5/site-packages/django/core/handlers/exception.py", line 41, in inner
    response = get_response(request)
  File "/home/python/.virtualenvs/django-py3-1.11/lib/python3.5/site-packages/django/core/handlers/base.py", line 187, in _get_response
    response = self.process_exception_by_middleware(e, request)
  File "/home/python/.virtualenvs/django-py3-1.11/lib/python3.5/site-packages/django/core/handlers/base.py", line 185, in _get_response
    response = wrapped_callback(request, *callback_args, **callback_kwargs)
  File "/home/python/.virtualenvs/django-py3-1.11/lib/python3.5/site-packages/django/views/decorators/csrf.py", line 58, in wrapped_view
    return view_func(*args, **kwargs)
  File "/home/python/.virtualenvs/django-py3-1.11/lib/python3.5/site-packages/django/views/generic/base.py", line 68, in view
    return self.dispatch(request, *args, **kwargs)
  File "/home/python/.virtualenvs/django-py3-1.11/lib/python3.5/site-packages/rest_framework/views.py", line 483, in dispatch
    response = self.handle_exception(exc)
  File "/home/python/.virtualenvs/django-py3-1.11/lib/python3.5/site-packages/rest_framework/views.py", line 443, in handle_exception
    self.raise_uncaught_exception(exc)
  File "/home/python/.virtualenvs/django-py3-1.11/lib/python3.5/site-packages/rest_framework/views.py", line 480, in dispatch
    response = handler(request, *args, **kwargs)
  File "/home/python/.virtualenvs/django-py3-1.11/lib/python3.5/site-packages/rest_framework/generics.py", line 192, in post
    return self.create(request, *args, **kwargs)
  File "/home/python/.virtualenvs/django-py3-1.11/lib/python3.5/site-packages/rest_framework/mixins.py", line 20, in create
    serializer.is_valid(raise_exception=True)
  File "/home/python/.virtualenvs/django-py3-1.11/lib/python3.5/site-packages/rest_framework/serializers.py", line 236, in is_valid
    self._validated_data = self.run_validation(self.initial_data)
  File "/home/python/.virtualenvs/django-py3-1.11/lib/python3.5/site-packages/rest_framework/serializers.py", line 434, in run_validation
    value = self.to_internal_value(data)
  File "/home/python/.virtualenvs/django-py3-1.11/lib/python3.5/site-packages/rest_framework/serializers.py", line 482, in to_internal_value
    fields = self._writable_fields
  File "/home/python/.virtualenvs/django-py3-1.11/lib/python3.5/site-packages/django/utils/functional.py", line 35, in __get__
    res = instance.__dict__[self.name] = self.func(instance)
  File "/home/python/.virtualenvs/django-py3-1.11/lib/python3.5/site-packages/rest_framework/serializers.py", line 370, in _writable_fields
    field for field in self.fields.values() if not field.read_only
  File "/home/python/.virtualenvs/django-py3-1.11/lib/python3.5/site-packages/rest_framework/serializers.py", line 363, in fields
    for key, value in self.get_fields().items():
  File "/home/python/.virtualenvs/django-py3-1.11/lib/python3.5/site-packages/rest_framework/serializers.py", line 1020, in get_fields
    field_names = self.get_field_names(declared_fields, info)
  File "/home/python/.virtualenvs/django-py3-1.11/lib/python3.5/site-packages/rest_framework/serializers.py", line 1121, in get_field_names
    serializer_class=self.__class__.__name__
AssertionError: The field 'allow' was declared on serializer CreateUserSerializer, but has not been included in the 'fields' option.
INFO 2018-09-19 15:09:46,434 basehttp 124 "GET /mobiles/15170444038/count/ HTTP/1.1" 200 34
INFO 2018-09-19 15:09:46,437 basehttp 124 "GET /usernames/15170444038/count/ HTTP/1.1" 200 36
ERROR 2018-09-19 15:09:46,496 basehttp 124 "POST /users/ HTTP/1.1" 500 19751
ERROR 2018-09-19 15:09:46,614 exception 135 Internal Server Error: /users/
Traceback (most recent call last):
  File "/home/python/.virtualenvs/django-py3-1.11/lib/python3.5/site-packages/django/core/handlers/exception.py", line 41, in inner
    response = get_response(request)
  File "/home/python/.virtualenvs/django-py3-1.11/lib/python3.5/site-packages/django/core/handlers/base.py", line 187, in _get_response
    response = self.process_exception_by_middleware(e, request)
  File "/home/python/.virtualenvs/django-py3-1.11/lib/python3.5/site-packages/django/core/handlers/base.py", line 185, in _get_response
    response = wrapped_callback(request, *callback_args, **callback_kwargs)
  File "/home/python/.virtualenvs/django-py3-1.11/lib/python3.5/site-packages/django/views/decorators/csrf.py", line 58, in wrapped_view
    return view_func(*args, **kwargs)
  File "/home/python/.virtualenvs/django-py3-1.11/lib/python3.5/site-packages/django/views/generic/base.py", line 68, in view
    return self.dispatch(request, *args, **kwargs)
  File "/home/python/.virtualenvs/django-py3-1.11/lib/python3.5/site-packages/rest_framework/views.py", line 483, in dispatch
    response = self.handle_exception(exc)
  File "/home/python/.virtualenvs/django-py3-1.11/lib/python3.5/site-packages/rest_framework/views.py", line 443, in handle_exception
    self.raise_uncaught_exception(exc)
  File "/home/python/.virtualenvs/django-py3-1.11/lib/python3.5/site-packages/rest_framework/views.py", line 480, in dispatch
    response = handler(request, *args, **kwargs)
  File "/home/python/.virtualenvs/django-py3-1.11/lib/python3.5/site-packages/rest_framework/generics.py", line 192, in post
    return self.create(request, *args, **kwargs)
  File "/home/python/.virtualenvs/django-py3-1.11/lib/python3.5/site-packages/rest_framework/mixins.py", line 20, in create
    serializer.is_valid(raise_exception=True)
  File "/home/python/.virtualenvs/django-py3-1.11/lib/python3.5/site-packages/rest_framework/serializers.py", line 236, in is_valid
    self._validated_data = self.run_validation(self.initial_data)
  File "/home/python/.virtualenvs/django-py3-1.11/lib/python3.5/site-packages/rest_framework/serializers.py", line 434, in run_validation
    value = self.to_internal_value(data)
  File "/home/python/.virtualenvs/django-py3-1.11/lib/python3.5/site-packages/rest_framework/serializers.py", line 482, in to_internal_value
    fields = self._writable_fields
  File "/home/python/.virtualenvs/django-py3-1.11/lib/python3.5/site-packages/django/utils/functional.py", line 35, in __get__
    res = instance.__dict__[self.name] = self.func(instance)
  File "/home/python/.virtualenvs/django-py3-1.11/lib/python3.5/site-packages/rest_framework/serializers.py", line 370, in _writable_fields
    field for field in self.fields.values() if not field.read_only
  File "/home/python/.virtualenvs/django-py3-1.11/lib/python3.5/site-packages/rest_framework/serializers.py", line 363, in fields
    for key, value in self.get_fields().items():
  File "/home/python/.virtualenvs/django-py3-1.11/lib/python3.5/site-packages/rest_framework/serializers.py", line 1020, in get_fields
    field_names = self.get_field_names(declared_fields, info)
  File "/home/python/.virtualenvs/django-py3-1.11/lib/python3.5/site-packages/rest_framework/serializers.py", line 1121, in get_field_names
    serializer_class=self.__class__.__name__
AssertionError: The field 'allow' was declared on serializer CreateUserSerializer, but has not been included in the 'fields' option.
ERROR 2018-09-19 15:09:46,637 basehttp 124 "POST /users/ HTTP/1.1" 500 19752
INFO 2018-09-19 15:09:46,646 basehttp 124 "GET /usernames/15170444038/count/ HTTP/1.1" 200 36
INFO 2018-09-19 15:09:46,648 basehttp 124 "GET /mobiles/15170444038/count/ HTTP/1.1" 200 34
INFO 2018-09-19 15:09:47,375 basehttp 124 "GET /mobiles/15170444038/count/ HTTP/1.1" 200 34
ERROR 2018-09-19 15:09:48,787 exception 135 Internal Server Error: /users/
Traceback (most recent call last):
  File "/home/python/.virtualenvs/django-py3-1.11/lib/python3.5/site-packages/django/core/handlers/exception.py", line 41, in inner
    response = get_response(request)
  File "/home/python/.virtualenvs/django-py3-1.11/lib/python3.5/site-packages/django/core/handlers/base.py", line 187, in _get_response
    response = self.process_exception_by_middleware(e, request)
  File "/home/python/.virtualenvs/django-py3-1.11/lib/python3.5/site-packages/django/core/handlers/base.py", line 185, in _get_response
    response = wrapped_callback(request, *callback_args, **callback_kwargs)
  File "/home/python/.virtualenvs/django-py3-1.11/lib/python3.5/site-packages/django/views/decorators/csrf.py", line 58, in wrapped_view
    return view_func(*args, **kwargs)
  File "/home/python/.virtualenvs/django-py3-1.11/lib/python3.5/site-packages/django/views/generic/base.py", line 68, in view
    return self.dispatch(request, *args, **kwargs)
  File "/home/python/.virtualenvs/django-py3-1.11/lib/python3.5/site-packages/rest_framework/views.py", line 483, in dispatch
    response = self.handle_exception(exc)
  File "/home/python/.virtualenvs/django-py3-1.11/lib/python3.5/site-packages/rest_framework/views.py", line 443, in handle_exception
    self.raise_uncaught_exception(exc)
  File "/home/python/.virtualenvs/django-py3-1.11/lib/python3.5/site-packages/rest_framework/views.py", line 480, in dispatch
    response = handler(request, *args, **kwargs)
  File "/home/python/.virtualenvs/django-py3-1.11/lib/python3.5/site-packages/rest_framework/generics.py", line 192, in post
    return self.create(request, *args, **kwargs)
  File "/home/python/.virtualenvs/django-py3-1.11/lib/python3.5/site-packages/rest_framework/mixins.py", line 20, in create
    serializer.is_valid(raise_exception=True)
  File "/home/python/.virtualenvs/django-py3-1.11/lib/python3.5/site-packages/rest_framework/serializers.py", line 236, in is_valid
    self._validated_data = self.run_validation(self.initial_data)
  File "/home/python/.virtualenvs/django-py3-1.11/lib/python3.5/site-packages/rest_framework/serializers.py", line 434, in run_validation
    value = self.to_internal_value(data)
  File "/home/python/.virtualenvs/django-py3-1.11/lib/python3.5/site-packages/rest_framework/serializers.py", line 482, in to_internal_value
    fields = self._writable_fields
  File "/home/python/.virtualenvs/django-py3-1.11/lib/python3.5/site-packages/django/utils/functional.py", line 35, in __get__
    res = instance.__dict__[self.name] = self.func(instance)
  File "/home/python/.virtualenvs/django-py3-1.11/lib/python3.5/site-packages/rest_framework/serializers.py", line 370, in _writable_fields
    field for field in self.fields.values() if not field.read_only
  File "/home/python/.virtualenvs/django-py3-1.11/lib/python3.5/site-packages/rest_framework/serializers.py", line 363, in fields
    for key, value in self.get_fields().items():
  File "/home/python/.virtualenvs/django-py3-1.11/lib/python3.5/site-packages/rest_framework/serializers.py", line 1020, in get_fields
    field_names = self.get_field_names(declared_fields, info)
  File "/home/python/.virtualenvs/django-py3-1.11/lib/python3.5/site-packages/rest_framework/serializers.py", line 1121, in get_field_names
    serializer_class=self.__class__.__name__
AssertionError: The field 'allow' was declared on serializer CreateUserSerializer, but has not been included in the 'fields' option.
INFO 2018-09-19 15:09:48,814 basehttp 124 "GET /mobiles/15170444038/count/ HTTP/1.1" 200 34
INFO 2018-09-19 15:09:48,817 basehttp 124 "GET /usernames/15170444038/count/ HTTP/1.1" 200 36
ERROR 2018-09-19 15:09:48,818 basehttp 124 "POST /users/ HTTP/1.1" 500 19752
WARNING 2018-09-19 15:10:08,439 tasks 30 发送验证码短信[失败][ mobile: 15170444038 ]
INFO 2018-09-19 15:10:08,440 basehttp 124 "GET /sms_codes/15170444038/ HTTP/1.1" 200 16
INFO 2018-09-19 15:12:09,238 basehttp 124 "GET /usernames/15170444038/count/ HTTP/1.1" 200 36
INFO 2018-09-19 15:12:16,923 basehttp 124 "GET /mobiles/15170444038/count/ HTTP/1.1" 200 34
INFO 2018-09-19 15:12:18,269 basehttp 124 "GET /mobiles/15170444038/count/ HTTP/1.1" 200 34
WARNING 2018-09-19 15:12:39,316 tasks 30 发送验证码短信[失败][ mobile: 15170444038 ]
INFO 2018-09-19 15:12:39,317 basehttp 124 "GET /sms_codes/15170444038/ HTTP/1.1" 200 16
INFO 2018-09-19 15:12:55,834 basehttp 124 "GET /mobiles/15170444038/count/ HTTP/1.1" 200 34
INFO 2018-09-19 15:12:55,837 basehttp 124 "GET /usernames/15170444038/count/ HTTP/1.1" 200 36
ERROR 2018-09-19 15:12:57,656 exception 135 Internal Server Error: /users/
Traceback (most recent call last):
  File "/home/python/.virtualenvs/django-py3-1.11/lib/python3.5/site-packages/django/core/handlers/exception.py", line 41, in inner
    response = get_response(request)
  File "/home/python/.virtualenvs/django-py3-1.11/lib/python3.5/site-packages/django/core/handlers/base.py", line 187, in _get_response
    response = self.process_exception_by_middleware(e, request)
  File "/home/python/.virtualenvs/django-py3-1.11/lib/python3.5/site-packages/django/core/handlers/base.py", line 185, in _get_response
    response = wrapped_callback(request, *callback_args, **callback_kwargs)
  File "/home/python/.virtualenvs/django-py3-1.11/lib/python3.5/site-packages/django/views/decorators/csrf.py", line 58, in wrapped_view
    return view_func(*args, **kwargs)
  File "/home/python/.virtualenvs/django-py3-1.11/lib/python3.5/site-packages/django/views/generic/base.py", line 68, in view
    return self.dispatch(request, *args, **kwargs)
  File "/home/python/.virtualenvs/django-py3-1.11/lib/python3.5/site-packages/rest_framework/views.py", line 483, in dispatch
    response = self.handle_exception(exc)
  File "/home/python/.virtualenvs/django-py3-1.11/lib/python3.5/site-packages/rest_framework/views.py", line 443, in handle_exception
    self.raise_uncaught_exception(exc)
  File "/home/python/.virtualenvs/django-py3-1.11/lib/python3.5/site-packages/rest_framework/views.py", line 480, in dispatch
    response = handler(request, *args, **kwargs)
  File "/home/python/.virtualenvs/django-py3-1.11/lib/python3.5/site-packages/rest_framework/generics.py", line 192, in post
    return self.create(request, *args, **kwargs)
  File "/home/python/.virtualenvs/django-py3-1.11/lib/python3.5/site-packages/rest_framework/mixins.py", line 20, in create
    serializer.is_valid(raise_exception=True)
  File "/home/python/.virtualenvs/django-py3-1.11/lib/python3.5/site-packages/rest_framework/serializers.py", line 236, in is_valid
    self._validated_data = self.run_validation(self.initial_data)
  File "/home/python/.virtualenvs/django-py3-1.11/lib/python3.5/site-packages/rest_framework/serializers.py", line 434, in run_validation
    value = self.to_internal_value(data)
  File "/home/python/.virtualenvs/django-py3-1.11/lib/python3.5/site-packages/rest_framework/serializers.py", line 482, in to_internal_value
    fields = self._writable_fields
  File "/home/python/.virtualenvs/django-py3-1.11/lib/python3.5/site-packages/django/utils/functional.py", line 35, in __get__
    res = instance.__dict__[self.name] = self.func(instance)
  File "/home/python/.virtualenvs/django-py3-1.11/lib/python3.5/site-packages/rest_framework/serializers.py", line 370, in _writable_fields
    field for field in self.fields.values() if not field.read_only
  File "/home/python/.virtualenvs/django-py3-1.11/lib/python3.5/site-packages/rest_framework/serializers.py", line 363, in fields
    for key, value in self.get_fields().items():
  File "/home/python/.virtualenvs/django-py3-1.11/lib/python3.5/site-packages/rest_framework/serializers.py", line 1020, in get_fields
    field_names = self.get_field_names(declared_fields, info)
  File "/home/python/.virtualenvs/django-py3-1.11/lib/python3.5/site-packages/rest_framework/serializers.py", line 1121, in get_field_names
    serializer_class=self.__class__.__name__
AssertionError: The field 'allow' was declared on serializer CreateUserSerializer, but has not been included in the 'fields' option.
INFO 2018-09-19 15:12:57,671 basehttp 124 "GET /usernames/15170444038/count/ HTTP/1.1" 200 36
INFO 2018-09-19 15:12:57,683 basehttp 124 "GET /mobiles/15170444038/count/ HTTP/1.1" 200 34
ERROR 2018-09-19 15:12:57,702 basehttp 124 "POST /users/ HTTP/1.1" 500 19751
INFO 2018-09-19 15:14:25,138 basehttp 124 "GET /usernames/15170444038/count/ HTTP/1.1" 200 36
INFO 2018-09-19 15:14:39,827 basehttp 124 "GET /mobiles/15170444038/count/ HTTP/1.1" 200 34
INFO 2018-09-19 15:14:41,010 basehttp 124 "GET /mobiles/15170444038/count/ HTTP/1.1" 200 34
ERROR 2018-09-19 15:14:48,649 exception 135 Internal Server Error: /users/
Traceback (most recent call last):
  File "/home/python/.virtualenvs/django-py3-1.11/lib/python3.5/site-packages/django/core/handlers/exception.py", line 41, in inner
    response = get_response(request)
  File "/home/python/.virtualenvs/django-py3-1.11/lib/python3.5/site-packages/django/core/handlers/base.py", line 187, in _get_response
    response = self.process_exception_by_middleware(e, request)
  File "/home/python/.virtualenvs/django-py3-1.11/lib/python3.5/site-packages/django/core/handlers/base.py", line 185, in _get_response
    response = wrapped_callback(request, *callback_args, **callback_kwargs)
  File "/home/python/.virtualenvs/django-py3-1.11/lib/python3.5/site-packages/django/views/decorators/csrf.py", line 58, in wrapped_view
    return view_func(*args, **kwargs)
  File "/home/python/.virtualenvs/django-py3-1.11/lib/python3.5/site-packages/django/views/generic/base.py", line 68, in view
    return self.dispatch(request, *args, **kwargs)
  File "/home/python/.virtualenvs/django-py3-1.11/lib/python3.5/site-packages/rest_framework/views.py", line 483, in dispatch
    response = self.handle_exception(exc)
  File "/home/python/.virtualenvs/django-py3-1.11/lib/python3.5/site-packages/rest_framework/views.py", line 443, in handle_exception
    self.raise_uncaught_exception(exc)
  File "/home/python/.virtualenvs/django-py3-1.11/lib/python3.5/site-packages/rest_framework/views.py", line 480, in dispatch
    response = handler(request, *args, **kwargs)
  File "/home/python/.virtualenvs/django-py3-1.11/lib/python3.5/site-packages/rest_framework/generics.py", line 192, in post
    return self.create(request, *args, **kwargs)
  File "/home/python/.virtualenvs/django-py3-1.11/lib/python3.5/site-packages/rest_framework/mixins.py", line 20, in create
    serializer.is_valid(raise_exception=True)
  File "/home/python/.virtualenvs/django-py3-1.11/lib/python3.5/site-packages/rest_framework/serializers.py", line 236, in is_valid
    self._validated_data = self.run_validation(self.initial_data)
  File "/home/python/.virtualenvs/django-py3-1.11/lib/python3.5/site-packages/rest_framework/serializers.py", line 434, in run_validation
    value = self.to_internal_value(data)
  File "/home/python/.virtualenvs/django-py3-1.11/lib/python3.5/site-packages/rest_framework/serializers.py", line 482, in to_internal_value
    fields = self._writable_fields
  File "/home/python/.virtualenvs/django-py3-1.11/lib/python3.5/site-packages/django/utils/functional.py", line 35, in __get__
    res = instance.__dict__[self.name] = self.func(instance)
  File "/home/python/.virtualenvs/django-py3-1.11/lib/python3.5/site-packages/rest_framework/serializers.py", line 370, in _writable_fields
    field for field in self.fields.values() if not field.read_only
  File "/home/python/.virtualenvs/django-py3-1.11/lib/python3.5/site-packages/rest_framework/serializers.py", line 363, in fields
    for key, value in self.get_fields().items():
  File "/home/python/.virtualenvs/django-py3-1.11/lib/python3.5/site-packages/rest_framework/serializers.py", line 1045, in get_fields
    source, info, model, depth
  File "/home/python/.virtualenvs/django-py3-1.11/lib/python3.5/site-packages/rest_framework/serializers.py", line 1190, in build_field
    return self.build_unknown_field(field_name, model_class)
  File "/home/python/.virtualenvs/django-py3-1.11/lib/python3.5/site-packages/rest_framework/serializers.py", line 1302, in build_unknown_field
    (field_name, model_class.__name__)
django.core.exceptions.ImproperlyConfigured: Field name `mobile` is not valid for model `User`.
INFO 2018-09-19 15:14:48,658 basehttp 124 "GET /mobiles/15170444038/count/ HTTP/1.1" 200 34
INFO 2018-09-19 15:14:48,662 basehttp 124 "GET /usernames/15170444038/count/ HTTP/1.1" 200 36
ERROR 2018-09-19 15:14:48,692 basehttp 124 "POST /users/ HTTP/1.1" 500 19791
WARNING 2018-09-19 15:15:02,048 tasks 30 发送验证码短信[失败][ mobile: 15170444038 ]
INFO 2018-09-19 15:15:02,049 basehttp 124 "GET /sms_codes/15170444038/ HTTP/1.1" 200 16
ERROR 2018-09-19 15:17:45,815 exception 135 Internal Server Error: /users/
Traceback (most recent call last):
  File "/home/python/.virtualenvs/django-py3-1.11/lib/python3.5/site-packages/django/core/handlers/exception.py", line 41, in inner
    response = get_response(request)
  File "/home/python/.virtualenvs/django-py3-1.11/lib/python3.5/site-packages/django/core/handlers/base.py", line 187, in _get_response
    response = self.process_exception_by_middleware(e, request)
  File "/home/python/.virtualenvs/django-py3-1.11/lib/python3.5/site-packages/django/core/handlers/base.py", line 185, in _get_response
    response = wrapped_callback(request, *callback_args, **callback_kwargs)
  File "/home/python/.virtualenvs/django-py3-1.11/lib/python3.5/site-packages/django/views/decorators/csrf.py", line 58, in wrapped_view
    return view_func(*args, **kwargs)
  File "/home/python/.virtualenvs/django-py3-1.11/lib/python3.5/site-packages/django/views/generic/base.py", line 68, in view
    return self.dispatch(request, *args, **kwargs)
  File "/home/python/.virtualenvs/django-py3-1.11/lib/python3.5/site-packages/rest_framework/views.py", line 483, in dispatch
    response = self.handle_exception(exc)
  File "/home/python/.virtualenvs/django-py3-1.11/lib/python3.5/site-packages/rest_framework/views.py", line 443, in handle_exception
    self.raise_uncaught_exception(exc)
  File "/home/python/.virtualenvs/django-py3-1.11/lib/python3.5/site-packages/rest_framework/views.py", line 480, in dispatch
    response = handler(request, *args, **kwargs)
  File "/home/python/.virtualenvs/django-py3-1.11/lib/python3.5/site-packages/rest_framework/generics.py", line 192, in post
    return self.create(request, *args, **kwargs)
  File "/home/python/.virtualenvs/django-py3-1.11/lib/python3.5/site-packages/rest_framework/mixins.py", line 20, in create
    serializer.is_valid(raise_exception=True)
  File "/home/python/.virtualenvs/django-py3-1.11/lib/python3.5/site-packages/rest_framework/serializers.py", line 236, in is_valid
    self._validated_data = self.run_validation(self.initial_data)
  File "/home/python/.virtualenvs/django-py3-1.11/lib/python3.5/site-packages/rest_framework/serializers.py", line 434, in run_validation
    value = self.to_internal_value(data)
  File "/home/python/.virtualenvs/django-py3-1.11/lib/python3.5/site-packages/rest_framework/serializers.py", line 482, in to_internal_value
    fields = self._writable_fields
  File "/home/python/.virtualenvs/django-py3-1.11/lib/python3.5/site-packages/django/utils/functional.py", line 35, in __get__
    res = instance.__dict__[self.name] = self.func(instance)
  File "/home/python/.virtualenvs/django-py3-1.11/lib/python3.5/site-packages/rest_framework/serializers.py", line 370, in _writable_fields
    field for field in self.fields.values() if not field.read_only
  File "/home/python/.virtualenvs/django-py3-1.11/lib/python3.5/site-packages/rest_framework/serializers.py", line 363, in fields
    for key, value in self.get_fields().items():
  File "/home/python/.virtualenvs/django-py3-1.11/lib/python3.5/site-packages/rest_framework/serializers.py", line 1045, in get_fields
    source, info, model, depth
  File "/home/python/.virtualenvs/django-py3-1.11/lib/python3.5/site-packages/rest_framework/serializers.py", line 1190, in build_field
    return self.build_unknown_field(field_name, model_class)
  File "/home/python/.virtualenvs/django-py3-1.11/lib/python3.5/site-packages/rest_framework/serializers.py", line 1302, in build_unknown_field
    (field_name, model_class.__name__)
django.core.exceptions.ImproperlyConfigured: Field name `mobile` is not valid for model `User`.
INFO 2018-09-19 15:17:45,841 basehttp 124 "GET /usernames/15170444038/count/ HTTP/1.1" 200 36
INFO 2018-09-19 15:17:45,846 basehttp 124 "GET /mobiles/15170444038/count/ HTTP/1.1" 200 34
ERROR 2018-09-19 15:17:45,865 basehttp 124 "POST /users/ HTTP/1.1" 500 19790
INFO 2018-09-19 15:20:35,811 basehttp 124 "GET /usernames/15170444038/count/ HTTP/1.1" 200 36
INFO 2018-09-19 15:20:47,336 basehttp 124 "GET /mobiles/15170444038/count/ HTTP/1.1" 200 34
INFO 2018-09-19 15:20:47,498 basehttp 124 "GET /mobiles/15170444038/count/ HTTP/1.1" 200 34
INFO 2018-09-19 15:21:08,523 basehttp 124 "GET /sms_codes/15170444038/ HTTP/1.1" 200 16
INFO 2018-09-19 15:21:18,088 basehttp 124 "GET /usernames/15170444038/count/ HTTP/1.1" 200 36
INFO 2018-09-19 15:21:18,090 basehttp 124 "GET /mobiles/15170444038/count/ HTTP/1.1" 200 34
INFO 2018-09-19 15:21:20,085 basehttp 124 "OPTIONS /users/ HTTP/1.1" 200 0
ERROR 2018-09-19 15:21:20,096 exception 135 Internal Server Error: /users/
Traceback (most recent call last):
  File "/home/python/.virtualenvs/django-py3-1.11/lib/python3.5/site-packages/django/core/handlers/exception.py", line 41, in inner
    response = get_response(request)
  File "/home/python/.virtualenvs/django-py3-1.11/lib/python3.5/site-packages/django/core/handlers/base.py", line 187, in _get_response
    response = self.process_exception_by_middleware(e, request)
  File "/home/python/.virtualenvs/django-py3-1.11/lib/python3.5/site-packages/django/core/handlers/base.py", line 185, in _get_response
    response = wrapped_callback(request, *callback_args, **callback_kwargs)
  File "/home/python/.virtualenvs/django-py3-1.11/lib/python3.5/site-packages/django/views/decorators/csrf.py", line 58, in wrapped_view
    return view_func(*args, **kwargs)
  File "/home/python/.virtualenvs/django-py3-1.11/lib/python3.5/site-packages/django/views/generic/base.py", line 68, in view
    return self.dispatch(request, *args, **kwargs)
  File "/home/python/.virtualenvs/django-py3-1.11/lib/python3.5/site-packages/rest_framework/views.py", line 483, in dispatch
    response = self.handle_exception(exc)
  File "/home/python/.virtualenvs/django-py3-1.11/lib/python3.5/site-packages/rest_framework/views.py", line 443, in handle_exception
    self.raise_uncaught_exception(exc)
  File "/home/python/.virtualenvs/django-py3-1.11/lib/python3.5/site-packages/rest_framework/views.py", line 480, in dispatch
    response = handler(request, *args, **kwargs)
  File "/home/python/.virtualenvs/django-py3-1.11/lib/python3.5/site-packages/rest_framework/generics.py", line 192, in post
    return self.create(request, *args, **kwargs)
  File "/home/python/.virtualenvs/django-py3-1.11/lib/python3.5/site-packages/rest_framework/mixins.py", line 20, in create
    serializer.is_valid(raise_exception=True)
  File "/home/python/.virtualenvs/django-py3-1.11/lib/python3.5/site-packages/rest_framework/serializers.py", line 236, in is_valid
    self._validated_data = self.run_validation(self.initial_data)
  File "/home/python/.virtualenvs/django-py3-1.11/lib/python3.5/site-packages/rest_framework/serializers.py", line 434, in run_validation
    value = self.to_internal_value(data)
  File "/home/python/.virtualenvs/django-py3-1.11/lib/python3.5/site-packages/rest_framework/serializers.py", line 482, in to_internal_value
    fields = self._writable_fields
  File "/home/python/.virtualenvs/django-py3-1.11/lib/python3.5/site-packages/django/utils/functional.py", line 35, in __get__
    res = instance.__dict__[self.name] = self.func(instance)
  File "/home/python/.virtualenvs/django-py3-1.11/lib/python3.5/site-packages/rest_framework/serializers.py", line 370, in _writable_fields
    field for field in self.fields.values() if not field.read_only
  File "/home/python/.virtualenvs/django-py3-1.11/lib/python3.5/site-packages/rest_framework/serializers.py", line 363, in fields
    for key, value in self.get_fields().items():
  File "/home/python/.virtualenvs/django-py3-1.11/lib/python3.5/site-packages/rest_framework/serializers.py", line 1045, in get_fields
    source, info, model, depth
  File "/home/python/.virtualenvs/django-py3-1.11/lib/python3.5/site-packages/rest_framework/serializers.py", line 1190, in build_field
    return self.build_unknown_field(field_name, model_class)
  File "/home/python/.virtualenvs/django-py3-1.11/lib/python3.5/site-packages/rest_framework/serializers.py", line 1302, in build_unknown_field
    (field_name, model_class.__name__)
django.core.exceptions.ImproperlyConfigured: Field name `mobile` is not valid for model `User`.
INFO 2018-09-19 15:21:20,099 basehttp 124 "GET /usernames/15170444038/count/ HTTP/1.1" 200 36
INFO 2018-09-19 15:21:20,111 basehttp 124 "GET /mobiles/15170444038/count/ HTTP/1.1" 200 34
ERROR 2018-09-19 15:21:20,136 basehttp 124 "POST /users/ HTTP/1.1" 500 19791
INFO 2018-09-19 15:23:27,572 basehttp 124 "GET /usernames/15170444038/count/ HTTP/1.1" 200 36
ERROR 2018-09-19 15:23:57,784 exception 135 Internal Server Error: /mobiles/15170444038/count/
Traceback (most recent call last):
  File "/home/python/.virtualenvs/django-py3-1.11/lib/python3.5/site-packages/django/core/handlers/exception.py", line 41, in inner
    response = get_response(request)
  File "/home/python/.virtualenvs/django-py3-1.11/lib/python3.5/site-packages/django/core/handlers/base.py", line 187, in _get_response
    response = self.process_exception_by_middleware(e, request)
  File "/home/python/.virtualenvs/django-py3-1.11/lib/python3.5/site-packages/django/core/handlers/base.py", line 185, in _get_response
    response = wrapped_callback(request, *callback_args, **callback_kwargs)
  File "/home/python/.virtualenvs/django-py3-1.11/lib/python3.5/site-packages/django/views/decorators/csrf.py", line 58, in wrapped_view
    return view_func(*args, **kwargs)
  File "/home/python/.virtualenvs/django-py3-1.11/lib/python3.5/site-packages/django/views/generic/base.py", line 68, in view
    return self.dispatch(request, *args, **kwargs)
  File "/home/python/.virtualenvs/django-py3-1.11/lib/python3.5/site-packages/rest_framework/views.py", line 483, in dispatch
    response = self.handle_exception(exc)
  File "/home/python/.virtualenvs/django-py3-1.11/lib/python3.5/site-packages/rest_framework/views.py", line 443, in handle_exception
    self.raise_uncaught_exception(exc)
  File "/home/python/.virtualenvs/django-py3-1.11/lib/python3.5/site-packages/rest_framework/views.py", line 480, in dispatch
    response = handler(request, *args, **kwargs)
  File "/home/python/Desktop/LiChengDjango/mdshop/mdshop/mdshop/apps/users/views.py", line 32, in get
    count = User.objects.filter(mobiles=mobile).count()
  File "/home/python/.virtualenvs/django-py3-1.11/lib/python3.5/site-packages/django/db/models/manager.py", line 85, in manager_method
    return getattr(self.get_queryset(), name)(*args, **kwargs)
  File "/home/python/.virtualenvs/django-py3-1.11/lib/python3.5/site-packages/django/db/models/query.py", line 784, in filter
    return self._filter_or_exclude(False, *args, **kwargs)
  File "/home/python/.virtualenvs/django-py3-1.11/lib/python3.5/site-packages/django/db/models/query.py", line 802, in _filter_or_exclude
    clone.query.add_q(Q(*args, **kwargs))
  File "/home/python/.virtualenvs/django-py3-1.11/lib/python3.5/site-packages/django/db/models/sql/query.py", line 1250, in add_q
    clause, _ = self._add_q(q_object, self.used_aliases)
  File "/home/python/.virtualenvs/django-py3-1.11/lib/python3.5/site-packages/django/db/models/sql/query.py", line 1276, in _add_q
    allow_joins=allow_joins, split_subq=split_subq,
  File "/home/python/.virtualenvs/django-py3-1.11/lib/python3.5/site-packages/django/db/models/sql/query.py", line 1154, in build_filter
    lookups, parts, reffed_expression = self.solve_lookup_type(arg)
  File "/home/python/.virtualenvs/django-py3-1.11/lib/python3.5/site-packages/django/db/models/sql/query.py", line 1034, in solve_lookup_type
    _, field, _, lookup_parts = self.names_to_path(lookup_splitted, self.get_meta())
  File "/home/python/.virtualenvs/django-py3-1.11/lib/python3.5/site-packages/django/db/models/sql/query.py", line 1352, in names_to_path
    "Choices are: %s" % (name, ", ".join(available)))
django.core.exceptions.FieldError: Cannot resolve keyword 'mobiles' into field. Choices are: date_joined, email, first_name, groups, id, is_active, is_staff, is_superuser, last_login, last_name, logentry, mobile, password, user_permissions, username
ERROR 2018-09-19 15:23:57,840 basehttp 124 "GET /mobiles/15170444038/count/ HTTP/1.1" 500 19878
ERROR 2018-09-19 15:23:57,945 exception 135 Internal Server Error: /mobiles/15170444038/count/
Traceback (most recent call last):
  File "/home/python/.virtualenvs/django-py3-1.11/lib/python3.5/site-packages/django/core/handlers/exception.py", line 41, in inner
    response = get_response(request)
  File "/home/python/.virtualenvs/django-py3-1.11/lib/python3.5/site-packages/django/core/handlers/base.py", line 187, in _get_response
    response = self.process_exception_by_middleware(e, request)
  File "/home/python/.virtualenvs/django-py3-1.11/lib/python3.5/site-packages/django/core/handlers/base.py", line 185, in _get_response
    response = wrapped_callback(request, *callback_args, **callback_kwargs)
  File "/home/python/.virtualenvs/django-py3-1.11/lib/python3.5/site-packages/django/views/decorators/csrf.py", line 58, in wrapped_view
    return view_func(*args, **kwargs)
  File "/home/python/.virtualenvs/django-py3-1.11/lib/python3.5/site-packages/django/views/generic/base.py", line 68, in view
    return self.dispatch(request, *args, **kwargs)
  File "/home/python/.virtualenvs/django-py3-1.11/lib/python3.5/site-packages/rest_framework/views.py", line 483, in dispatch
    response = self.handle_exception(exc)
  File "/home/python/.virtualenvs/django-py3-1.11/lib/python3.5/site-packages/rest_framework/views.py", line 443, in handle_exception
    self.raise_uncaught_exception(exc)
  File "/home/python/.virtualenvs/django-py3-1.11/lib/python3.5/site-packages/rest_framework/views.py", line 480, in dispatch
    response = handler(request, *args, **kwargs)
  File "/home/python/Desktop/LiChengDjango/mdshop/mdshop/mdshop/apps/users/views.py", line 32, in get
    count = User.objects.filter(mobiles=mobile).count()
  File "/home/python/.virtualenvs/django-py3-1.11/lib/python3.5/site-packages/django/db/models/manager.py", line 85, in manager_method
    return getattr(self.get_queryset(), name)(*args, **kwargs)
  File "/home/python/.virtualenvs/django-py3-1.11/lib/python3.5/site-packages/django/db/models/query.py", line 784, in filter
    return self._filter_or_exclude(False, *args, **kwargs)
  File "/home/python/.virtualenvs/django-py3-1.11/lib/python3.5/site-packages/django/db/models/query.py", line 802, in _filter_or_exclude
    clone.query.add_q(Q(*args, **kwargs))
  File "/home/python/.virtualenvs/django-py3-1.11/lib/python3.5/site-packages/django/db/models/sql/query.py", line 1250, in add_q
    clause, _ = self._add_q(q_object, self.used_aliases)
  File "/home/python/.virtualenvs/django-py3-1.11/lib/python3.5/site-packages/django/db/models/sql/query.py", line 1276, in _add_q
    allow_joins=allow_joins, split_subq=split_subq,
  File "/home/python/.virtualenvs/django-py3-1.11/lib/python3.5/site-packages/django/db/models/sql/query.py", line 1154, in build_filter
    lookups, parts, reffed_expression = self.solve_lookup_type(arg)
  File "/home/python/.virtualenvs/django-py3-1.11/lib/python3.5/site-packages/django/db/models/sql/query.py", line 1034, in solve_lookup_type
    _, field, _, lookup_parts = self.names_to_path(lookup_splitted, self.get_meta())
  File "/home/python/.virtualenvs/django-py3-1.11/lib/python3.5/site-packages/django/db/models/sql/query.py", line 1352, in names_to_path
    "Choices are: %s" % (name, ", ".join(available)))
django.core.exceptions.FieldError: Cannot resolve keyword 'mobiles' into field. Choices are: date_joined, email, first_name, groups, id, is_active, is_staff, is_superuser, last_login, last_name, logentry, mobile, password, user_permissions, username
ERROR 2018-09-19 15:23:57,972 basehttp 124 "GET /mobiles/15170444038/count/ HTTP/1.1" 500 19878
INFO 2018-09-19 15:24:19,020 basehttp 124 "GET /sms_codes/15170444038/ HTTP/1.1" 200 16
ERROR 2018-09-19 15:24:29,485 exception 135 Internal Server Error: /mobiles/15170444038/count/
Traceback (most recent call last):
  File "/home/python/.virtualenvs/django-py3-1.11/lib/python3.5/site-packages/django/core/handlers/exception.py", line 41, in inner
    response = get_response(request)
  File "/home/python/.virtualenvs/django-py3-1.11/lib/python3.5/site-packages/django/core/handlers/base.py", line 187, in _get_response
    response = self.process_exception_by_middleware(e, request)
  File "/home/python/.virtualenvs/django-py3-1.11/lib/python3.5/site-packages/django/core/handlers/base.py", line 185, in _get_response
    response = wrapped_callback(request, *callback_args, **callback_kwargs)
  File "/home/python/.virtualenvs/django-py3-1.11/lib/python3.5/site-packages/django/views/decorators/csrf.py", line 58, in wrapped_view
    return view_func(*args, **kwargs)
  File "/home/python/.virtualenvs/django-py3-1.11/lib/python3.5/site-packages/django/views/generic/base.py", line 68, in view
    return self.dispatch(request, *args, **kwargs)
  File "/home/python/.virtualenvs/django-py3-1.11/lib/python3.5/site-packages/rest_framework/views.py", line 483, in dispatch
    response = self.handle_exception(exc)
  File "/home/python/.virtualenvs/django-py3-1.11/lib/python3.5/site-packages/rest_framework/views.py", line 443, in handle_exception
    self.raise_uncaught_exception(exc)
  File "/home/python/.virtualenvs/django-py3-1.11/lib/python3.5/site-packages/rest_framework/views.py", line 480, in dispatch
    response = handler(request, *args, **kwargs)
  File "/home/python/Desktop/LiChengDjango/mdshop/mdshop/mdshop/apps/users/views.py", line 32, in get
    count = User.objects.filter(mobiles=mobile).count()
  File "/home/python/.virtualenvs/django-py3-1.11/lib/python3.5/site-packages/django/db/models/manager.py", line 85, in manager_method
    return getattr(self.get_queryset(), name)(*args, **kwargs)
  File "/home/python/.virtualenvs/django-py3-1.11/lib/python3.5/site-packages/django/db/models/query.py", line 784, in filter
    return self._filter_or_exclude(False, *args, **kwargs)
  File "/home/python/.virtualenvs/django-py3-1.11/lib/python3.5/site-packages/django/db/models/query.py", line 802, in _filter_or_exclude
    clone.query.add_q(Q(*args, **kwargs))
  File "/home/python/.virtualenvs/django-py3-1.11/lib/python3.5/site-packages/django/db/models/sql/query.py", line 1250, in add_q
    clause, _ = self._add_q(q_object, self.used_aliases)
  File "/home/python/.virtualenvs/django-py3-1.11/lib/python3.5/site-packages/django/db/models/sql/query.py", line 1276, in _add_q
    allow_joins=allow_joins, split_subq=split_subq,
  File "/home/python/.virtualenvs/django-py3-1.11/lib/python3.5/site-packages/django/db/models/sql/query.py", line 1154, in build_filter
    lookups, parts, reffed_expression = self.solve_lookup_type(arg)
  File "/home/python/.virtualenvs/django-py3-1.11/lib/python3.5/site-packages/django/db/models/sql/query.py", line 1034, in solve_lookup_type
    _, field, _, lookup_parts = self.names_to_path(lookup_splitted, self.get_meta())
  File "/home/python/.virtualenvs/django-py3-1.11/lib/python3.5/site-packages/django/db/models/sql/query.py", line 1352, in names_to_path
    "Choices are: %s" % (name, ", ".join(available)))
django.core.exceptions.FieldError: Cannot resolve keyword 'mobiles' into field. Choices are: date_joined, email, first_name, groups, id, is_active, is_staff, is_superuser, last_login, last_name, logentry, mobile, password, user_permissions, username
WARNING 2018-09-19 15:24:29,507 basehttp 124 "POST /users/ HTTP/1.1" 400 43
INFO 2018-09-19 15:24:29,511 basehttp 124 "GET /usernames/15170444038/count/ HTTP/1.1" 200 36
ERROR 2018-09-19 15:24:29,535 basehttp 124 "GET /mobiles/15170444038/count/ HTTP/1.1" 500 19878
ERROR 2018-09-19 15:24:33,841 exception 135 Internal Server Error: /mobiles/15170444038/count/
Traceback (most recent call last):
  File "/home/python/.virtualenvs/django-py3-1.11/lib/python3.5/site-packages/django/core/handlers/exception.py", line 41, in inner
    response = get_response(request)
  File "/home/python/.virtualenvs/django-py3-1.11/lib/python3.5/site-packages/django/core/handlers/base.py", line 187, in _get_response
    response = self.process_exception_by_middleware(e, request)
  File "/home/python/.virtualenvs/django-py3-1.11/lib/python3.5/site-packages/django/core/handlers/base.py", line 185, in _get_response
    response = wrapped_callback(request, *callback_args, **callback_kwargs)
  File "/home/python/.virtualenvs/django-py3-1.11/lib/python3.5/site-packages/django/views/decorators/csrf.py", line 58, in wrapped_view
    return view_func(*args, **kwargs)
  File "/home/python/.virtualenvs/django-py3-1.11/lib/python3.5/site-packages/django/views/generic/base.py", line 68, in view
    return self.dispatch(request, *args, **kwargs)
  File "/home/python/.virtualenvs/django-py3-1.11/lib/python3.5/site-packages/rest_framework/views.py", line 483, in dispatch
    response = self.handle_exception(exc)
  File "/home/python/.virtualenvs/django-py3-1.11/lib/python3.5/site-packages/rest_framework/views.py", line 443, in handle_exception
    self.raise_uncaught_exception(exc)
  File "/home/python/.virtualenvs/django-py3-1.11/lib/python3.5/site-packages/rest_framework/views.py", line 480, in dispatch
    response = handler(request, *args, **kwargs)
  File "/home/python/Desktop/LiChengDjango/mdshop/mdshop/mdshop/apps/users/views.py", line 32, in get
    count = User.objects.filter(mobiles=mobile).count()
  File "/home/python/.virtualenvs/django-py3-1.11/lib/python3.5/site-packages/django/db/models/manager.py", line 85, in manager_method
    return getattr(self.get_queryset(), name)(*args, **kwargs)
  File "/home/python/.virtualenvs/django-py3-1.11/lib/python3.5/site-packages/django/db/models/query.py", line 784, in filter
    return self._filter_or_exclude(False, *args, **kwargs)
  File "/home/python/.virtualenvs/django-py3-1.11/lib/python3.5/site-packages/django/db/models/query.py", line 802, in _filter_or_exclude
    clone.query.add_q(Q(*args, **kwargs))
  File "/home/python/.virtualenvs/django-py3-1.11/lib/python3.5/site-packages/django/db/models/sql/query.py", line 1250, in add_q
    clause, _ = self._add_q(q_object, self.used_aliases)
  File "/home/python/.virtualenvs/django-py3-1.11/lib/python3.5/site-packages/django/db/models/sql/query.py", line 1276, in _add_q
    allow_joins=allow_joins, split_subq=split_subq,
  File "/home/python/.virtualenvs/django-py3-1.11/lib/python3.5/site-packages/django/db/models/sql/query.py", line 1154, in build_filter
    lookups, parts, reffed_expression = self.solve_lookup_type(arg)
  File "/home/python/.virtualenvs/django-py3-1.11/lib/python3.5/site-packages/django/db/models/sql/query.py", line 1034, in solve_lookup_type
    _, field, _, lookup_parts = self.names_to_path(lookup_splitted, self.get_meta())
  File "/home/python/.virtualenvs/django-py3-1.11/lib/python3.5/site-packages/django/db/models/sql/query.py", line 1352, in names_to_path
    "Choices are: %s" % (name, ", ".join(available)))
django.core.exceptions.FieldError: Cannot resolve keyword 'mobiles' into field. Choices are: date_joined, email, first_name, groups, id, is_active, is_staff, is_superuser, last_login, last_name, logentry, mobile, password, user_permissions, username
INFO 2018-09-19 15:24:33,865 basehttp 124 "GET /usernames/15170444038/count/ HTTP/1.1" 200 36
WARNING 2018-09-19 15:24:33,870 basehttp 124 "POST /users/ HTTP/1.1" 400 43
ERROR 2018-09-19 15:24:33,886 basehttp 124 "GET /mobiles/15170444038/count/ HTTP/1.1" 500 19878
INFO 2018-09-19 15:25:09,974 basehttp 124 "GET /usernames/15170444038/count/ HTTP/1.1" 200 36
ERROR 2018-09-19 15:25:32,307 exception 135 Internal Server Error: /mobiles/15170444038/count/
Traceback (most recent call last):
  File "/home/python/.virtualenvs/django-py3-1.11/lib/python3.5/site-packages/django/core/handlers/exception.py", line 41, in inner
    response = get_response(request)
  File "/home/python/.virtualenvs/django-py3-1.11/lib/python3.5/site-packages/django/core/handlers/base.py", line 187, in _get_response
    response = self.process_exception_by_middleware(e, request)
  File "/home/python/.virtualenvs/django-py3-1.11/lib/python3.5/site-packages/django/core/handlers/base.py", line 185, in _get_response
    response = wrapped_callback(request, *callback_args, **callback_kwargs)
  File "/home/python/.virtualenvs/django-py3-1.11/lib/python3.5/site-packages/django/views/decorators/csrf.py", line 58, in wrapped_view
    return view_func(*args, **kwargs)
  File "/home/python/.virtualenvs/django-py3-1.11/lib/python3.5/site-packages/django/views/generic/base.py", line 68, in view
    return self.dispatch(request, *args, **kwargs)
  File "/home/python/.virtualenvs/django-py3-1.11/lib/python3.5/site-packages/rest_framework/views.py", line 483, in dispatch
    response = self.handle_exception(exc)
  File "/home/python/.virtualenvs/django-py3-1.11/lib/python3.5/site-packages/rest_framework/views.py", line 443, in handle_exception
    self.raise_uncaught_exception(exc)
  File "/home/python/.virtualenvs/django-py3-1.11/lib/python3.5/site-packages/rest_framework/views.py", line 480, in dispatch
    response = handler(request, *args, **kwargs)
  File "/home/python/Desktop/LiChengDjango/mdshop/mdshop/mdshop/apps/users/views.py", line 32, in get
    count = User.objects.filter(mobiles=mobile).count()
  File "/home/python/.virtualenvs/django-py3-1.11/lib/python3.5/site-packages/django/db/models/manager.py", line 85, in manager_method
    return getattr(self.get_queryset(), name)(*args, **kwargs)
  File "/home/python/.virtualenvs/django-py3-1.11/lib/python3.5/site-packages/django/db/models/query.py", line 784, in filter
    return self._filter_or_exclude(False, *args, **kwargs)
  File "/home/python/.virtualenvs/django-py3-1.11/lib/python3.5/site-packages/django/db/models/query.py", line 802, in _filter_or_exclude
    clone.query.add_q(Q(*args, **kwargs))
  File "/home/python/.virtualenvs/django-py3-1.11/lib/python3.5/site-packages/django/db/models/sql/query.py", line 1250, in add_q
    clause, _ = self._add_q(q_object, self.used_aliases)
  File "/home/python/.virtualenvs/django-py3-1.11/lib/python3.5/site-packages/django/db/models/sql/query.py", line 1276, in _add_q
    allow_joins=allow_joins, split_subq=split_subq,
  File "/home/python/.virtualenvs/django-py3-1.11/lib/python3.5/site-packages/django/db/models/sql/query.py", line 1154, in build_filter
    lookups, parts, reffed_expression = self.solve_lookup_type(arg)
  File "/home/python/.virtualenvs/django-py3-1.11/lib/python3.5/site-packages/django/db/models/sql/query.py", line 1034, in solve_lookup_type
    _, field, _, lookup_parts = self.names_to_path(lookup_splitted, self.get_meta())
  File "/home/python/.virtualenvs/django-py3-1.11/lib/python3.5/site-packages/django/db/models/sql/query.py", line 1352, in names_to_path
    "Choices are: %s" % (name, ", ".join(available)))
django.core.exceptions.FieldError: Cannot resolve keyword 'mobiles' into field. Choices are: date_joined, email, first_name, groups, id, is_active, is_staff, is_superuser, last_login, last_name, logentry, mobile, password, user_permissions, username
ERROR 2018-09-19 15:25:32,384 basehttp 124 "GET /mobiles/15170444038/count/ HTTP/1.1" 500 19878
ERROR 2018-09-19 15:25:32,500 exception 135 Internal Server Error: /mobiles/15170444038/count/
Traceback (most recent call last):
  File "/home/python/.virtualenvs/django-py3-1.11/lib/python3.5/site-packages/django/core/handlers/exception.py", line 41, in inner
    response = get_response(request)
  File "/home/python/.virtualenvs/django-py3-1.11/lib/python3.5/site-packages/django/core/handlers/base.py", line 187, in _get_response
    response = self.process_exception_by_middleware(e, request)
  File "/home/python/.virtualenvs/django-py3-1.11/lib/python3.5/site-packages/django/core/handlers/base.py", line 185, in _get_response
    response = wrapped_callback(request, *callback_args, **callback_kwargs)
  File "/home/python/.virtualenvs/django-py3-1.11/lib/python3.5/site-packages/django/views/decorators/csrf.py", line 58, in wrapped_view
    return view_func(*args, **kwargs)
  File "/home/python/.virtualenvs/django-py3-1.11/lib/python3.5/site-packages/django/views/generic/base.py", line 68, in view
    return self.dispatch(request, *args, **kwargs)
  File "/home/python/.virtualenvs/django-py3-1.11/lib/python3.5/site-packages/rest_framework/views.py", line 483, in dispatch
    response = self.handle_exception(exc)
  File "/home/python/.virtualenvs/django-py3-1.11/lib/python3.5/site-packages/rest_framework/views.py", line 443, in handle_exception
    self.raise_uncaught_exception(exc)
  File "/home/python/.virtualenvs/django-py3-1.11/lib/python3.5/site-packages/rest_framework/views.py", line 480, in dispatch
    response = handler(request, *args, **kwargs)
  File "/home/python/Desktop/LiChengDjango/mdshop/mdshop/mdshop/apps/users/views.py", line 32, in get
    count = User.objects.filter(mobiles=mobile).count()
  File "/home/python/.virtualenvs/django-py3-1.11/lib/python3.5/site-packages/django/db/models/manager.py", line 85, in manager_method
    return getattr(self.get_queryset(), name)(*args, **kwargs)
  File "/home/python/.virtualenvs/django-py3-1.11/lib/python3.5/site-packages/django/db/models/query.py", line 784, in filter
    return self._filter_or_exclude(False, *args, **kwargs)
  File "/home/python/.virtualenvs/django-py3-1.11/lib/python3.5/site-packages/django/db/models/query.py", line 802, in _filter_or_exclude
    clone.query.add_q(Q(*args, **kwargs))
  File "/home/python/.virtualenvs/django-py3-1.11/lib/python3.5/site-packages/django/db/models/sql/query.py", line 1250, in add_q
    clause, _ = self._add_q(q_object, self.used_aliases)
  File "/home/python/.virtualenvs/django-py3-1.11/lib/python3.5/site-packages/django/db/models/sql/query.py", line 1276, in _add_q
    allow_joins=allow_joins, split_subq=split_subq,
  File "/home/python/.virtualenvs/django-py3-1.11/lib/python3.5/site-packages/django/db/models/sql/query.py", line 1154, in build_filter
    lookups, parts, reffed_expression = self.solve_lookup_type(arg)
  File "/home/python/.virtualenvs/django-py3-1.11/lib/python3.5/site-packages/django/db/models/sql/query.py", line 1034, in solve_lookup_type
    _, field, _, lookup_parts = self.names_to_path(lookup_splitted, self.get_meta())
  File "/home/python/.virtualenvs/django-py3-1.11/lib/python3.5/site-packages/django/db/models/sql/query.py", line 1352, in names_to_path
    "Choices are: %s" % (name, ", ".join(available)))
django.core.exceptions.FieldError: Cannot resolve keyword 'mobiles' into field. Choices are: date_joined, email, first_name, groups, id, is_active, is_staff, is_superuser, last_login, last_name, logentry, mobile, password, user_permissions, username
ERROR 2018-09-19 15:25:32,529 basehttp 124 "GET /mobiles/15170444038/count/ HTTP/1.1" 500 19878
INFO 2018-09-19 15:25:53,539 basehttp 124 "GET /sms_codes/15170444038/ HTTP/1.1" 200 16
INFO 2018-09-19 15:26:23,108 basehttp 124 "GET /mobiles/15170444038/count/ HTTP/1.1" 200 34
INFO 2018-09-19 15:26:23,112 basehttp 124 "GET /usernames/15170444038/count/ HTTP/1.1" 200 36
WARNING 2018-09-19 15:26:23,119 basehttp 124 "POST /users/ HTTP/1.1" 400 43
INFO 2018-09-19 15:28:53,919 basehttp 124 "GET /usernames/licheng/count/ HTTP/1.1" 200 32
INFO 2018-09-19 15:29:14,920 basehttp 124 "GET /mobiles/15170444038/count/ HTTP/1.1" 200 34
INFO 2018-09-19 15:29:15,118 basehttp 124 "GET /mobiles/15170444038/count/ HTTP/1.1" 200 34
INFO 2018-09-19 15:29:36,168 basehttp 124 "GET /sms_codes/15170444038/ HTTP/1.1" 200 16
INFO 2018-09-19 15:29:40,248 basehttp 124 "GET /mobiles/15170444038/count/ HTTP/1.1" 200 34
INFO 2018-09-19 15:29:40,249 basehttp 124 "GET /usernames/licheng/count/ HTTP/1.1" 200 32
WARNING 2018-09-19 15:29:40,255 basehttp 124 "POST /users/ HTTP/1.1" 400 43
INFO 2018-09-19 15:30:09,878 basehttp 124 "GET /mobiles/15170444038/count/ HTTP/1.1" 200 34
INFO 2018-09-19 15:30:09,883 basehttp 124 "GET /usernames/licheng/count/ HTTP/1.1" 200 32
INFO 2018-09-19 15:30:09,939 basehttp 124 "POST /users/ HTTP/1.1" 201 143
INFO 2018-09-19 15:42:12,698 basehttp 124 "OPTIONS /authorizations/ HTTP/1.1" 200 0
INFO 2018-09-19 15:42:12,750 basehttp 124 "POST /authorizations/ HTTP/1.1" 200 209
WARNING 2018-09-19 15:42:24,802 basehttp 124 "POST /authorizations/ HTTP/1.1" 400 67
WARNING 2018-09-19 15:51:10,785 basehttp 124 "POST /authorizations/ HTTP/1.1" 400 67
WARNING 2018-09-19 15:51:16,006 basehttp 124 "POST /authorizations/ HTTP/1.1" 400 67
WARNING 2018-09-19 15:51:31,076 basehttp 124 "POST /authorizations/ HTTP/1.1" 400 67
WARNING 2018-09-19 15:51:40,928 basehttp 124 "POST /authorizations/ HTTP/1.1" 400 67
WARNING 2018-09-19 15:51:43,210 basehttp 124 "POST /authorizations/ HTTP/1.1" 400 67
WARNING 2018-09-19 15:52:09,290 basehttp 124 "POST /authorizations/ HTTP/1.1" 400 67
INFO 2018-09-19 15:56:15,488 basehttp 124 "GET /usernames/15170444038/count/ HTTP/1.1" 200 36
INFO 2018-09-19 15:56:55,380 basehttp 124 "GET /usernames/licheng/count/ HTTP/1.1" 200 32
INFO 2018-09-19 15:57:08,581 basehttp 124 "GET /usernames/lichenga/count/ HTTP/1.1" 200 33
INFO 2018-09-19 15:57:43,430 basehttp 124 "GET /mobiles/15170444038/count/ HTTP/1.1" 200 34
INFO 2018-09-19 15:57:46,698 basehttp 124 "GET /sms_codes/15170444038/ HTTP/1.1" 200 16
INFO 2018-09-19 15:57:46,702 basehttp 124 "GET /mobiles/15170444038/count/ HTTP/1.1" 200 34
INFO 2018-09-19 15:58:10,334 basehttp 124 "OPTIONS /authorizations/ HTTP/1.1" 200 0
WARNING 2018-09-19 15:58:10,345 basehttp 124 "POST /authorizations/ HTTP/1.1" 400 67
WARNING 2018-09-19 15:58:16,400 basehttp 124 "POST /authorizations/ HTTP/1.1" 400 67
WARNING 2018-09-19 15:58:17,166 basehttp 124 "POST /authorizations/ HTTP/1.1" 400 67
WARNING 2018-09-19 15:58:17,342 basehttp 124 "POST /authorizations/ HTTP/1.1" 400 67
WARNING 2018-09-19 15:58:17,538 basehttp 124 "POST /authorizations/ HTTP/1.1" 400 67
WARNING 2018-09-19 15:58:17,728 basehttp 124 "POST /authorizations/ HTTP/1.1" 400 67
WARNING 2018-09-19 15:58:18,179 basehttp 124 "POST /authorizations/ HTTP/1.1" 400 67
WARNING 2018-09-19 15:58:18,375 basehttp 124 "POST /authorizations/ HTTP/1.1" 400 67
INFO 2018-09-19 15:58:23,835 basehttp 124 "GET /usernames/lichenga/count/ HTTP/1.1" 200 33
INFO 2018-09-19 15:58:42,823 basehttp 124 "GET /mobiles/15166666666/count/ HTTP/1.1" 200 34
INFO 2018-09-19 15:58:42,964 basehttp 124 "GET /sms_codes/15166666666/ HTTP/1.1" 200 16
INFO 2018-09-19 15:58:42,967 basehttp 124 "GET /mobiles/15166666666/count/ HTTP/1.1" 200 34
INFO 2018-09-19 15:58:47,978 basehttp 124 "OPTIONS /users/ HTTP/1.1" 200 0
INFO 2018-09-19 15:58:47,993 basehttp 124 "GET /mobiles/15166666666/count/ HTTP/1.1" 200 34
INFO 2018-09-19 15:58:47,999 basehttp 124 "GET /usernames/lichenga/count/ HTTP/1.1" 200 33
INFO 2018-09-19 15:58:48,040 basehttp 124 "POST /users/ HTTP/1.1" 201 320
WARNING 2018-09-19 15:59:04,785 basehttp 124 "POST /authorizations/ HTTP/1.1" 400 67
WARNING 2018-09-19 16:00:15,864 basehttp 124 "POST /authorizations/ HTTP/1.1" 400 67
WARNING 2018-09-19 16:00:17,425 basehttp 124 "POST /authorizations/ HTTP/1.1" 400 67
INFO 2018-09-19 16:00:21,542 basehttp 124 "POST /authorizations/ HTTP/1.1" 200 209
INFO 2018-09-19 16:30:54,509 basehttp 124 "GET /oauth/qq/authorization/?state=/ HTTP/1.1" 200 175
WARNING 2018-09-19 16:31:28,013 base 152 Not Found: /oauth/qq/user/
WARNING 2018-09-19 16:31:28,014 basehttp 124 "GET /oauth/qq/user/?code=F3DA32DAC2F3732D803F26C6E50C3D6F HTTP/1.1" 404 3088
INFO 2018-09-19 16:33:05,709 basehttp 124 "GET /oauth/qq/authorization/?state=/ HTTP/1.1" 200 175
WARNING 2018-09-19 16:33:30,924 base 152 Not Found: /oauth/qq/user/
WARNING 2018-09-19 16:33:30,928 basehttp 124 "GET /oauth/qq/user/?code=672F0A58C5CE2B469F2D690BFA893016 HTTP/1.1" 404 3088
INFO 2018-09-19 16:48:00,015 basehttp 124 "GET /oauth/qq/authorization/?state=/ HTTP/1.1" 200 200
WARNING 2018-09-19 16:48:13,071 base 152 Not Found: /oauth/qq/user/
WARNING 2018-09-19 16:48:13,073 basehttp 124 "GET /oauth/qq/user/?code=8084CB0273E6B34447417783F2F44537 HTTP/1.1" 404 3253
INFO 2018-09-19 16:49:07,143 basehttp 124 "GET /oauth/qq/user/?code=9ACF6D2E0BA3CAADF61E372F327E96A9 HTTP/1.1" 200 0
INFO 2018-09-19 21:09:59,630 basehttp 124 "GET /oauth/qq/user/?code=F4E559614F0B91014073B5D1AA7DC0C0 HTTP/1.1" 200 51
INFO 2018-09-19 21:10:10,559 basehttp 124 "GET /sms_codes/15170444038/ HTTP/1.1" 200 16
INFO 2018-09-19 21:10:16,790 basehttp 124 "OPTIONS /oauth/qq/user/ HTTP/1.1" 200 0
WARNING 2018-09-19 21:10:16,794 basehttp 124 "POST /oauth/qq/user/ HTTP/1.1" 405 46
INFO 2018-09-19 21:38:02,233 basehttp 124 "GET /oauth/qq/user/?code=54DE46FC161254D77BB1E8ABB229AE90 HTTP/1.1" 200 190
INFO 2018-09-19 21:40:17,974 basehttp 124 "OPTIONS /oauth/qq/user/ HTTP/1.1" 200 0
WARNING 2018-09-19 21:40:17,981 basehttp 124 "POST /oauth/qq/user/ HTTP/1.1" 405 46
INFO 2018-09-19 21:40:20,630 basehttp 124 "GET /sms_codes/15170444038/ HTTP/1.1" 200 16
WARNING 2018-09-19 21:40:23,149 basehttp 124 "POST /oauth/qq/user/ HTTP/1.1" 405 46
ERROR 2018-09-19 21:40:40,163 exception 135 Internal Server Error: /oauth/qq/user/
Traceback (most recent call last):
  File "/home/python/.virtualenvs/django-py3-1.11/lib/python3.5/site-packages/django/core/handlers/exception.py", line 41, in inner
    response = get_response(request)
  File "/home/python/.virtualenvs/django-py3-1.11/lib/python3.5/site-packages/django/core/handlers/base.py", line 187, in _get_response
    response = self.process_exception_by_middleware(e, request)
  File "/home/python/.virtualenvs/django-py3-1.11/lib/python3.5/site-packages/django/core/handlers/base.py", line 185, in _get_response
    response = wrapped_callback(request, *callback_args, **callback_kwargs)
  File "/home/python/.virtualenvs/django-py3-1.11/lib/python3.5/site-packages/django/views/decorators/csrf.py", line 58, in wrapped_view
    return view_func(*args, **kwargs)
  File "/home/python/.virtualenvs/django-py3-1.11/lib/python3.5/site-packages/django/views/generic/base.py", line 68, in view
    return self.dispatch(request, *args, **kwargs)
  File "/home/python/.virtualenvs/django-py3-1.11/lib/python3.5/site-packages/rest_framework/views.py", line 483, in dispatch
    response = self.handle_exception(exc)
  File "/home/python/.virtualenvs/django-py3-1.11/lib/python3.5/site-packages/rest_framework/views.py", line 443, in handle_exception
    self.raise_uncaught_exception(exc)
  File "/home/python/.virtualenvs/django-py3-1.11/lib/python3.5/site-packages/rest_framework/views.py", line 480, in dispatch
    response = handler(request, *args, **kwargs)
  File "/home/python/Desktop/LiChengDjango/mdshop/mdshop/mdshop/apps/oauth/views.py", line 48, in get
    access_token = oauth.get_access_token(code)
  File "/home/python/.virtualenvs/django-py3-1.11/lib/python3.5/site-packages/QQLoginTool/QQtool.py", line 63, in get_access_token
    raise Exception('access_token获取失败')
Exception: access_token获取失败
ERROR 2018-09-19 21:40:40,254 basehttp 124 "GET /oauth/qq/user/?code=54DE46FC161254D77BB1E8ABB229AE90 HTTP/1.1" 500 18737
INFO 2018-09-19 22:20:41,722 basehttp 124 "GET /oauth/qq/user/?code=D19A9EC35BD485C0E7E3D23F7F1790FF HTTP/1.1" 200 190
INFO 2018-09-19 22:20:49,822 basehttp 124 "GET /sms_codes/15170444038/ HTTP/1.1" 200 16
INFO 2018-09-19 22:20:55,352 basehttp 124 "OPTIONS /oauth/qq/user/ HTTP/1.1" 200 0
WARNING 2018-09-19 22:20:55,358 basehttp 124 "POST /oauth/qq/user/ HTTP/1.1" 400 46
ERROR 2018-09-19 22:24:54,453 exception 135 Internal Server Error: /oauth/qq/user/
Traceback (most recent call last):
  File "/home/python/.virtualenvs/django-py3-1.11/lib/python3.5/site-packages/django/core/handlers/exception.py", line 41, in inner
    response = get_response(request)
  File "/home/python/.virtualenvs/django-py3-1.11/lib/python3.5/site-packages/django/core/handlers/base.py", line 187, in _get_response
    response = self.process_exception_by_middleware(e, request)
  File "/home/python/.virtualenvs/django-py3-1.11/lib/python3.5/site-packages/django/core/handlers/base.py", line 185, in _get_response
    response = wrapped_callback(request, *callback_args, **callback_kwargs)
  File "/home/python/.virtualenvs/django-py3-1.11/lib/python3.5/site-packages/django/views/decorators/csrf.py", line 58, in wrapped_view
    return view_func(*args, **kwargs)
  File "/home/python/.virtualenvs/django-py3-1.11/lib/python3.5/site-packages/django/views/generic/base.py", line 68, in view
    return self.dispatch(request, *args, **kwargs)
  File "/home/python/.virtualenvs/django-py3-1.11/lib/python3.5/site-packages/rest_framework/views.py", line 483, in dispatch
    response = self.handle_exception(exc)
  File "/home/python/.virtualenvs/django-py3-1.11/lib/python3.5/site-packages/rest_framework/views.py", line 443, in handle_exception
    self.raise_uncaught_exception(exc)
  File "/home/python/.virtualenvs/django-py3-1.11/lib/python3.5/site-packages/rest_framework/views.py", line 480, in dispatch
    response = handler(request, *args, **kwargs)
  File "/home/python/Desktop/LiChengDjango/mdshop/mdshop/mdshop/apps/oauth/views.py", line 50, in get
    access_token = oauth.get_access_token(code)
  File "/home/python/.virtualenvs/django-py3-1.11/lib/python3.5/site-packages/QQLoginTool/QQtool.py", line 63, in get_access_token
    raise Exception('access_token获取失败')
Exception: access_token获取失败
ERROR 2018-09-19 22:24:54,484 basehttp 124 "GET /oauth/qq/user/?code=D19A9EC35BD485C0E7E3D23F7F1790FF HTTP/1.1" 500 18737
INFO 2018-09-19 22:25:04,341 basehttp 124 "GET /oauth/qq/authorization/?next=/ HTTP/1.1" 200 200
INFO 2018-09-19 22:25:18,569 basehttp 124 "GET /oauth/qq/user/?code=CAED16D59B765E92C0D08FD9927E0643 HTTP/1.1" 200 190
INFO 2018-09-19 22:25:25,575 basehttp 124 "GET /sms_codes/15170444038/ HTTP/1.1" 200 16
INFO 2018-09-19 22:25:38,006 basehttp 124 "OPTIONS /oauth/qq/user/ HTTP/1.1" 200 0
WARNING 2018-09-19 22:25:38,011 basehttp 124 "POST /oauth/qq/user/ HTTP/1.1" 400 46
WARNING 2018-09-19 22:28:24,350 basehttp 124 "POST /oauth/qq/user/ HTTP/1.1" 400 46
WARNING 2018-09-19 22:30:14,205 basehttp 124 "POST /oauth/qq/user/ HTTP/1.1" 400 46
WARNING 2018-09-19 22:30:51,500 basehttp 124 "POST /oauth/qq/user/ HTTP/1.1" 400 46
WARNING 2018-09-19 22:31:58,156 basehttp 124 "POST /oauth/qq/user/ HTTP/1.1" 400 46
WARNING 2018-09-19 22:33:52,457 basehttp 124 "POST /oauth/qq/user/ HTTP/1.1" 400 46
WARNING 2018-09-19 22:34:28,287 basehttp 124 "POST /oauth/qq/user/ HTTP/1.1" 400 37
INFO 2018-09-19 22:39:31,908 basehttp 124 "OPTIONS /oauth/qq/user/ HTTP/1.1" 200 0
WARNING 2018-09-19 22:39:31,931 basehttp 124 "POST /oauth/qq/user/ HTTP/1.1" 400 37
WARNING 2018-09-19 22:39:42,547 basehttp 124 "POST /oauth/qq/user/ HTTP/1.1" 400 37
WARNING 2018-09-19 22:39:43,320 basehttp 124 "POST /oauth/qq/user/ HTTP/1.1" 400 37
WARNING 2018-09-19 22:39:43,799 basehttp 124 "POST /oauth/qq/user/ HTTP/1.1" 400 37
WARNING 2018-09-19 22:39:43,961 basehttp 124 "POST /oauth/qq/user/ HTTP/1.1" 400 37
WARNING 2018-09-19 22:39:44,238 basehttp 124 "POST /oauth/qq/user/ HTTP/1.1" 400 37
WARNING 2018-09-19 22:39:44,409 basehttp 124 "POST /oauth/qq/user/ HTTP/1.1" 400 37
WARNING 2018-09-19 22:39:44,581 basehttp 124 "POST /oauth/qq/user/ HTTP/1.1" 400 37
ERROR 2018-09-19 22:43:19,529 exception 135 Internal Server Error: /oauth/qq/user/
Traceback (most recent call last):
  File "/home/python/.virtualenvs/django-py3-1.11/lib/python3.5/site-packages/django/core/handlers/exception.py", line 41, in inner
    response = get_response(request)
  File "/home/python/.virtualenvs/django-py3-1.11/lib/python3.5/site-packages/django/core/handlers/base.py", line 187, in _get_response
    response = self.process_exception_by_middleware(e, request)
  File "/home/python/.virtualenvs/django-py3-1.11/lib/python3.5/site-packages/django/core/handlers/base.py", line 185, in _get_response
    response = wrapped_callback(request, *callback_args, **callback_kwargs)
  File "/home/python/.virtualenvs/django-py3-1.11/lib/python3.5/site-packages/django/views/decorators/csrf.py", line 58, in wrapped_view
    return view_func(*args, **kwargs)
  File "/home/python/.virtualenvs/django-py3-1.11/lib/python3.5/site-packages/django/views/generic/base.py", line 68, in view
    return self.dispatch(request, *args, **kwargs)
  File "/home/python/.virtualenvs/django-py3-1.11/lib/python3.5/site-packages/rest_framework/views.py", line 483, in dispatch
    response = self.handle_exception(exc)
  File "/home/python/.virtualenvs/django-py3-1.11/lib/python3.5/site-packages/rest_framework/views.py", line 443, in handle_exception
    self.raise_uncaught_exception(exc)
  File "/home/python/.virtualenvs/django-py3-1.11/lib/python3.5/site-packages/rest_framework/views.py", line 480, in dispatch
    response = handler(request, *args, **kwargs)
  File "/home/python/Desktop/LiChengDjango/mdshop/mdshop/mdshop/apps/oauth/views.py", line 50, in get
    access_token = oauth.get_access_token(code)
  File "/home/python/.virtualenvs/django-py3-1.11/lib/python3.5/site-packages/QQLoginTool/QQtool.py", line 63, in get_access_token
    raise Exception('access_token获取失败')
Exception: access_token获取失败
ERROR 2018-09-19 22:43:19,558 basehttp 124 "GET /oauth/qq/user/?code=CAED16D59B765E92C0D08FD9927E0643 HTTP/1.1" 500 18737
INFO 2018-09-19 22:43:29,963 basehttp 124 "GET /oauth/qq/authorization/?next=/ HTTP/1.1" 200 200
INFO 2018-09-19 22:43:44,079 basehttp 124 "GET /oauth/qq/user/?code=D4242F6929BCCAC503A98C0E2B9030CE HTTP/1.1" 200 190
INFO 2018-09-19 22:43:46,396 basehttp 124 "GET /sms_codes/15170444038/ HTTP/1.1" 200 16
INFO 2018-09-19 22:43:51,543 basehttp 124 "OPTIONS /oauth/qq/user/ HTTP/1.1" 200 0
WARNING 2018-09-19 22:43:51,549 basehttp 124 "POST /oauth/qq/user/ HTTP/1.1" 400 37
WARNING 2018-09-19 22:45:55,290 basehttp 124 "POST /oauth/qq/user/ HTTP/1.1" 400 37
INFO 2018-09-19 22:46:29,637 basehttp 124 "GET /sms_codes/15170444038/ HTTP/1.1" 200 16
WARNING 2018-09-19 22:46:31,698 basehttp 124 "POST /oauth/qq/user/ HTTP/1.1" 400 37
INFO 2018-09-19 22:47:14,389 basehttp 124 "POST /oauth/qq/user/ HTTP/1.1" 201 220
INFO 2018-09-19 22:47:34,093 basehttp 124 "GET /oauth/qq/authorization/?next=/ HTTP/1.1" 200 200
INFO 2018-09-19 22:47:54,387 basehttp 124 "GET /oauth/qq/user/?code=0D56D007980CD593C2AFE1AB6BC44E7C HTTP/1.1" 200 209
INFO 2018-09-19 22:51:36,163 basehttp 124 "GET /oauth/qq/authorization/?next=/ HTTP/1.1" 200 175
INFO 2018-09-19 22:51:44,336 basehttp 124 "GET /oauth/qq/user/?code=4C30294D11CAE10C4A77B1D85C49C170 HTTP/1.1" 200 209
INFO 2018-09-19 22:51:53,469 basehttp 124 "OPTIONS /user/ HTTP/1.1" 200 0
WARNING 2018-09-19 22:51:53,513 base 152 Not Found: /user/
WARNING 2018-09-19 22:51:53,515 basehttp 124 "GET /user/ HTTP/1.1" 404 2957
INFO 2018-09-19 22:53:36,141 basehttp 124 "GET /oauth/qq/authorization/?next=/ HTTP/1.1" 200 175
INFO 2018-09-19 22:53:47,178 basehttp 124 "GET /oauth/qq/user/?code=14DDE8649F4009442F7D18193ADBDB8B HTTP/1.1" 200 190
INFO 2018-09-19 22:54:01,953 basehttp 124 "GET /sms_codes/13278684038/ HTTP/1.1" 200 16
INFO 2018-09-19 22:54:07,033 basehttp 124 "OPTIONS /oauth/qq/user/ HTTP/1.1" 200 0
INFO 2018-09-19 22:54:07,085 basehttp 124 "POST /oauth/qq/user/ HTTP/1.1" 201 229
INFO 2018-09-19 22:55:28,794 basehttp 124 "GET /oauth/qq/authorization/?next=/ HTTP/1.1" 200 175
INFO 2018-09-19 22:55:37,076 basehttp 124 "GET /oauth/qq/user/?code=8F3E8F53D06FC2560D8706B2CFEA0713 HTTP/1.1" 200 218
INFO 2018-09-19 22:55:46,734 basehttp 124 "GET /oauth/qq/authorization/?next=/ HTTP/1.1" 200 175
INFO 2018-09-19 22:56:09,574 basehttp 124 "GET /oauth/qq/user/?code=B5CCCFD7B4421E696700AF7C604E3899 HTTP/1.1" 200 190
INFO 2018-09-19 22:56:16,627 basehttp 124 "GET /sms_codes/15170444039/ HTTP/1.1" 200 16
INFO 2018-09-19 22:56:20,989 basehttp 124 "OPTIONS /oauth/qq/user/ HTTP/1.1" 200 0
WARNING 2018-09-19 22:56:20,995 basehttp 124 "POST /oauth/qq/user/ HTTP/1.1" 400 65
WARNING 2018-09-19 22:56:22,066 basehttp 124 "POST /oauth/qq/user/ HTTP/1.1" 400 65
WARNING 2018-09-19 22:56:25,909 basehttp 124 "POST /oauth/qq/user/ HTTP/1.1" 400 65
WARNING 2018-09-19 22:56:51,238 basehttp 124 "POST /oauth/qq/user/ HTTP/1.1" 400 37
WARNING 2018-09-19 22:57:28,302 basehttp 124 "POST /oauth/qq/user/ HTTP/1.1" 400 65
WARNING 2018-09-19 22:57:28,879 basehttp 124 "POST /oauth/qq/user/ HTTP/1.1" 400 65
WARNING 2018-09-19 22:57:31,432 basehttp 124 "POST /oauth/qq/user/ HTTP/1.1" 400 65
WARNING 2018-09-19 22:57:31,602 basehttp 124 "POST /oauth/qq/user/ HTTP/1.1" 400 65
WARNING 2018-09-19 22:57:31,788 basehttp 124 "POST /oauth/qq/user/ HTTP/1.1" 400 65
WARNING 2018-09-19 22:57:31,978 basehttp 124 "POST /oauth/qq/user/ HTTP/1.1" 400 65
WARNING 2018-09-19 22:57:33,629 basehttp 124 "POST /oauth/qq/user/ HTTP/1.1" 400 65
WARNING 2018-09-19 22:57:33,815 basehttp 124 "POST /oauth/qq/user/ HTTP/1.1" 400 65
WARNING 2018-09-19 22:57:34,190 basehttp 124 "POST /oauth/qq/user/ HTTP/1.1" 400 65
WARNING 2018-09-19 22:57:34,373 basehttp 124 "POST /oauth/qq/user/ HTTP/1.1" 400 65
WARNING 2018-09-19 22:57:34,574 basehttp 124 "POST /oauth/qq/user/ HTTP/1.1" 400 65
WARNING 2018-09-19 22:57:34,766 basehttp 124 "POST /oauth/qq/user/ HTTP/1.1" 400 65
WARNING 2018-09-19 22:58:01,910 basehttp 124 "POST /oauth/qq/user/ HTTP/1.1" 400 37
WARNING 2018-09-19 22:58:03,100 basehttp 124 "POST /oauth/qq/user/ HTTP/1.1" 400 37
WARNING 2018-09-19 22:58:46,760 basehttp 124 "POST /oauth/qq/user/ HTTP/1.1" 400 37
WARNING 2018-09-19 22:58:47,266 basehttp 124 "POST /oauth/qq/user/ HTTP/1.1" 400 37
WARNING 2018-09-19 22:58:47,459 basehttp 124 "POST /oauth/qq/user/ HTTP/1.1" 400 37
WARNING 2018-09-19 22:58:47,655 basehttp 124 "POST /oauth/qq/user/ HTTP/1.1" 400 37
WARNING 2018-09-19 22:58:47,842 basehttp 124 "POST /oauth/qq/user/ HTTP/1.1" 400 37
WARNING 2018-09-19 22:58:48,187 basehttp 124 "POST /oauth/qq/user/ HTTP/1.1" 400 37
WARNING 2018-09-19 22:58:48,381 basehttp 124 "POST /oauth/qq/user/ HTTP/1.1" 400 37
WARNING 2018-09-19 22:58:48,566 basehttp 124 "POST /oauth/qq/user/ HTTP/1.1" 400 37
WARNING 2018-09-19 22:59:04,009 basehttp 124 "POST /oauth/qq/user/ HTTP/1.1" 400 37
INFO 2018-09-20 09:01:32,976 basehttp 124 "GET /oauth/qq/authorization/?next=/ HTTP/1.1" 200 175
INFO 2018-09-20 09:01:38,561 basehttp 124 "GET /oauth/qq/authorization/?next=/ HTTP/1.1" 200 175
INFO 2018-09-20 09:01:52,657 basehttp 124 "OPTIONS /authorizations/ HTTP/1.1" 200 0
WARNING 2018-09-20 09:01:52,701 basehttp 124 "POST /authorizations/ HTTP/1.1" 400 67
WARNING 2018-09-20 09:01:57,951 basehttp 124 "POST /authorizations/ HTTP/1.1" 400 67
INFO 2018-09-20 09:02:18,633 basehttp 124 "POST /authorizations/ HTTP/1.1" 200 211
INFO 2018-09-20 09:02:25,175 basehttp 124 "OPTIONS /user/ HTTP/1.1" 200 0
INFO 2018-09-20 09:02:25,252 basehttp 124 "GET /user/ HTTP/1.1" 200 85
INFO 2018-09-20 09:02:25,260 basehttp 124 "OPTIONS /browse_histories/ HTTP/1.1" 200 0
WARNING 2018-09-20 09:02:25,271 base 152 Not Found: /browse_histories/
WARNING 2018-09-20 09:02:25,272 basehttp 124 "GET /browse_histories/ HTTP/1.1" 404 3148
INFO 2018-09-20 09:17:17,732 basehttp 124 "OPTIONS /user/ HTTP/1.1" 200 0
INFO 2018-09-20 09:17:17,795 basehttp 124 "GET /user/ HTTP/1.1" 200 85
INFO 2018-09-20 09:17:17,843 basehttp 124 "OPTIONS /browse_histories/ HTTP/1.1" 200 0
WARNING 2018-09-20 09:17:17,855 base 152 Not Found: /browse_histories/
WARNING 2018-09-20 09:17:17,857 basehttp 124 "GET /browse_histories/ HTTP/1.1" 404 3304
INFO 2018-09-20 09:17:38,907 basehttp 124 "OPTIONS /emails/ HTTP/1.1" 200 0
WARNING 2018-09-20 09:17:38,917 base 152 Not Found: /emails/
WARNING 2018-09-20 09:17:38,918 basehttp 124 "PUT /emails/ HTTP/1.1" 404 3274
WARNING 2018-09-20 09:17:42,049 base 152 Not Found: /emails/
WARNING 2018-09-20 09:17:42,050 basehttp 124 "PUT /emails/ HTTP/1.1" 404 3274
INFO 2018-09-20 09:18:06,747 basehttp 124 "GET /user/ HTTP/1.1" 200 85
WARNING 2018-09-20 09:18:06,785 base 152 Not Found: /browse_histories/
WARNING 2018-09-20 09:18:06,786 basehttp 124 "GET /browse_histories/ HTTP/1.1" 404 3305
INFO 2018-09-20 09:18:25,557 basehttp 124 "PUT /emails/ HTTP/1.1" 200 36
INFO 2018-09-20 09:18:44,468 basehttp 124 "GET /user/ HTTP/1.1" 200 102
WARNING 2018-09-20 09:18:44,492 base 152 Not Found: /browse_histories/
WARNING 2018-09-20 09:18:44,492 basehttp 124 "GET /browse_histories/ HTTP/1.1" 404 3305
INFO 2018-09-20 09:20:03,767 basehttp 124 "OPTIONS /authorizations/ HTTP/1.1" 200 0
INFO 2018-09-20 09:20:03,808 basehttp 124 "POST /authorizations/ HTTP/1.1" 200 234
INFO 2018-09-20 09:20:19,040 basehttp 124 "GET /user/ HTTP/1.1" 200 102
WARNING 2018-09-20 09:20:19,086 base 152 Not Found: /browse_histories/
WARNING 2018-09-20 09:20:19,087 basehttp 124 "GET /browse_histories/ HTTP/1.1" 404 3305
INFO 2018-09-20 09:20:47,537 basehttp 124 "POST /authorizations/ HTTP/1.1" 200 209
INFO 2018-09-20 09:21:02,446 basehttp 124 "GET /user/ HTTP/1.1" 200 84
WARNING 2018-09-20 09:21:02,484 base 152 Not Found: /browse_histories/
WARNING 2018-09-20 09:21:02,486 basehttp 124 "GET /browse_histories/ HTTP/1.1" 404 3305
INFO 2018-09-20 09:21:44,189 basehttp 124 "PUT /emails/ HTTP/1.1" 200 36
INFO 2018-09-20 09:22:36,899 basehttp 124 "GET /oauth/qq/authorization/?next=/ HTTP/1.1" 200 175
INFO 2018-09-20 09:23:57,836 basehttp 124 "GET /usernames/chengli/count/ HTTP/1.1" 200 32
INFO 2018-09-20 09:24:23,056 basehttp 124 "GET /mobiles/15666666666/count/ HTTP/1.1" 200 34
INFO 2018-09-20 09:24:24,062 basehttp 124 "GET /sms_codes/15666666666/ HTTP/1.1" 200 16
INFO 2018-09-20 09:24:24,072 basehttp 124 "GET /mobiles/15666666666/count/ HTTP/1.1" 200 34
INFO 2018-09-20 09:24:31,146 basehttp 124 "OPTIONS /users/ HTTP/1.1" 200 0
INFO 2018-09-20 09:24:31,183 basehttp 124 "GET /usernames/chengli/count/ HTTP/1.1" 200 32
INFO 2018-09-20 09:24:31,190 basehttp 124 "GET /mobiles/15666666666/count/ HTTP/1.1" 200 34
INFO 2018-09-20 09:24:31,249 basehttp 124 "POST /users/ HTTP/1.1" 201 318
INFO 2018-09-20 09:24:52,968 basehttp 124 "OPTIONS /user/ HTTP/1.1" 200 0
INFO 2018-09-20 09:24:53,049 basehttp 124 "GET /user/ HTTP/1.1" 200 84
INFO 2018-09-20 09:24:53,064 basehttp 124 "OPTIONS /browse_histories/ HTTP/1.1" 200 0
WARNING 2018-09-20 09:24:53,092 base 152 Not Found: /browse_histories/
WARNING 2018-09-20 09:24:53,094 basehttp 124 "GET /browse_histories/ HTTP/1.1" 404 3305
INFO 2018-09-20 09:25:13,619 basehttp 124 "OPTIONS /emails/ HTTP/1.1" 200 0
INFO 2018-09-20 09:25:33,783 basehttp 124 "PUT /emails/ HTTP/1.1" 200 36
INFO 2018-09-20 09:46:38,587 basehttp 124 "OPTIONS /user/ HTTP/1.1" 200 0
INFO 2018-09-20 09:46:38,663 basehttp 124 "GET /user/ HTTP/1.1" 200 101
INFO 2018-09-20 09:46:38,677 basehttp 124 "OPTIONS /browse_histories/ HTTP/1.1" 200 0
WARNING 2018-09-20 09:46:38,690 base 152 Not Found: /browse_histories/
WARNING 2018-09-20 09:46:38,691 basehttp 124 "GET /browse_histories/ HTTP/1.1" 404 3305
INFO 2018-09-20 09:46:46,123 basehttp 124 "OPTIONS /emails/ HTTP/1.1" 200 0
INFO 2018-09-20 09:46:46,215 basehttp 124 "PUT /emails/ HTTP/1.1" 200 36
INFO 2018-09-20 09:52:45,943 basehttp 124 "GET /user/ HTTP/1.1" 200 101
WARNING 2018-09-20 09:52:45,971 base 152 Not Found: /browse_histories/
WARNING 2018-09-20 09:52:45,972 basehttp 124 "GET /browse_histories/ HTTP/1.1" 404 3305
INFO 2018-09-20 09:52:46,613 basehttp 124 "PUT /emails/ HTTP/1.1" 200 36
INFO 2018-09-20 09:56:00,253 basehttp 124 "GET /user/ HTTP/1.1" 200 101
WARNING 2018-09-20 09:56:00,275 base 152 Not Found: /browse_histories/
WARNING 2018-09-20 09:56:00,276 basehttp 124 "GET /browse_histories/ HTTP/1.1" 404 3305
INFO 2018-09-20 09:56:16,661 basehttp 124 "GET /usernames/zxwzxw/count/ HTTP/1.1" 200 31
INFO 2018-09-20 09:56:33,080 basehttp 124 "GET /mobiles/15999999999/count/ HTTP/1.1" 200 34
INFO 2018-09-20 09:56:33,637 basehttp 124 "GET /sms_codes/15999999999/ HTTP/1.1" 200 16
INFO 2018-09-20 09:56:33,646 basehttp 124 "GET /mobiles/15999999999/count/ HTTP/1.1" 200 34
INFO 2018-09-20 09:56:37,464 basehttp 124 "GET /mobiles/15999999999/count/ HTTP/1.1" 200 34
INFO 2018-09-20 09:56:37,468 basehttp 124 "GET /usernames/zxwzxw/count/ HTTP/1.1" 200 31
INFO 2018-09-20 09:56:39,088 basehttp 124 "OPTIONS /users/ HTTP/1.1" 200 0
INFO 2018-09-20 09:56:39,110 basehttp 124 "GET /usernames/zxwzxw/count/ HTTP/1.1" 200 31
INFO 2018-09-20 09:56:39,113 basehttp 124 "GET /mobiles/15999999999/count/ HTTP/1.1" 200 34
INFO 2018-09-20 09:56:39,153 basehttp 124 "POST /users/ HTTP/1.1" 201 316
INFO 2018-09-20 09:56:41,205 basehttp 124 "OPTIONS /user/ HTTP/1.1" 200 0
INFO 2018-09-20 09:56:41,246 basehttp 124 "GET /user/ HTTP/1.1" 200 83
INFO 2018-09-20 09:56:41,258 basehttp 124 "OPTIONS /browse_histories/ HTTP/1.1" 200 0
WARNING 2018-09-20 09:56:41,271 base 152 Not Found: /browse_histories/
WARNING 2018-09-20 09:56:41,272 basehttp 124 "GET /browse_histories/ HTTP/1.1" 404 3305
INFO 2018-09-20 09:57:05,664 basehttp 124 "OPTIONS /emails/ HTTP/1.1" 200 0
INFO 2018-09-20 09:57:05,726 basehttp 124 "PUT /emails/ HTTP/1.1" 200 36
INFO 2018-09-20 09:58:02,077 basehttp 124 "OPTIONS /authorizations/ HTTP/1.1" 200 0
WARNING 2018-09-20 09:58:02,120 basehttp 124 "POST /authorizations/ HTTP/1.1" 400 67
INFO 2018-09-20 09:58:10,380 basehttp 124 "POST /authorizations/ HTTP/1.1" 200 232
INFO 2018-09-20 09:58:53,528 basehttp 124 "GET /user/ HTTP/1.1" 200 101
WARNING 2018-09-20 09:58:53,546 base 152 Not Found: /browse_histories/
WARNING 2018-09-20 09:58:53,547 basehttp 124 "GET /browse_histories/ HTTP/1.1" 404 3305
INFO 2018-09-20 09:58:54,848 basehttp 124 "GET /user/ HTTP/1.1" 200 101
WARNING 2018-09-20 09:58:54,875 base 152 Not Found: /browse_histories/
WARNING 2018-09-20 09:58:54,876 basehttp 124 "GET /browse_histories/ HTTP/1.1" 404 3305
WARNING 2018-09-20 09:59:09,418 basehttp 124 "POST /authorizations/ HTTP/1.1" 400 67
WARNING 2018-09-20 09:59:14,912 basehttp 124 "POST /authorizations/ HTTP/1.1" 400 67
WARNING 2018-09-20 09:59:16,795 basehttp 124 "POST /authorizations/ HTTP/1.1" 400 67
WARNING 2018-09-20 09:59:28,163 basehttp 124 "POST /authorizations/ HTTP/1.1" 400 67
INFO 2018-09-20 09:59:34,063 basehttp 124 "POST /authorizations/ HTTP/1.1" 200 229
INFO 2018-09-20 09:59:36,132 basehttp 124 "GET /user/ HTTP/1.1" 200 100
WARNING 2018-09-20 09:59:36,157 base 152 Not Found: /browse_histories/
WARNING 2018-09-20 09:59:36,158 basehttp 124 "GET /browse_histories/ HTTP/1.1" 404 3305
INFO 2018-09-20 09:59:37,746 basehttp 124 "GET /user/ HTTP/1.1" 200 100
WARNING 2018-09-20 09:59:37,776 base 152 Not Found: /browse_histories/
WARNING 2018-09-20 09:59:37,777 basehttp 124 "GET /browse_histories/ HTTP/1.1" 404 3305
INFO 2018-09-20 09:59:38,625 basehttp 124 "PUT /emails/ HTTP/1.1" 200 36
INFO 2018-09-20 10:00:08,124 basehttp 124 "POST /authorizations/ HTTP/1.1" 200 232
INFO 2018-09-20 10:00:14,812 basehttp 124 "GET /user/ HTTP/1.1" 200 101
WARNING 2018-09-20 10:00:14,832 base 152 Not Found: /browse_histories/
WARNING 2018-09-20 10:00:14,833 basehttp 124 "GET /browse_histories/ HTTP/1.1" 404 3305
INFO 2018-09-20 10:02:56,163 basehttp 124 "GET /usernames/lqlqlq/count/ HTTP/1.1" 200 31
INFO 2018-09-20 10:08:25,318 basehttp 124 "GET /usernames/chengli/count/ HTTP/1.1" 200 32
INFO 2018-09-20 10:08:38,135 basehttp 124 "GET /mobiles/15444444444/count/ HTTP/1.1" 200 34
INFO 2018-09-20 10:08:39,922 basehttp 124 "GET /sms_codes/15444444444/ HTTP/1.1" 200 16
INFO 2018-09-20 10:08:39,932 basehttp 124 "GET /mobiles/15444444444/count/ HTTP/1.1" 200 34
INFO 2018-09-20 10:08:45,590 basehttp 124 "OPTIONS /users/ HTTP/1.1" 200 0
INFO 2018-09-20 10:08:45,606 basehttp 124 "GET /usernames/chengli/count/ HTTP/1.1" 200 32
INFO 2018-09-20 10:08:45,609 basehttp 124 "GET /mobiles/15444444444/count/ HTTP/1.1" 200 34
INFO 2018-09-20 10:08:45,649 basehttp 124 "POST /users/ HTTP/1.1" 201 318
INFO 2018-09-20 10:08:48,263 basehttp 124 "OPTIONS /user/ HTTP/1.1" 200 0
INFO 2018-09-20 10:08:48,327 basehttp 124 "GET /user/ HTTP/1.1" 200 84
INFO 2018-09-20 10:08:48,353 basehttp 124 "OPTIONS /browse_histories/ HTTP/1.1" 200 0
WARNING 2018-09-20 10:08:48,368 base 152 Not Found: /browse_histories/
WARNING 2018-09-20 10:08:48,369 basehttp 124 "GET /browse_histories/ HTTP/1.1" 404 3305
INFO 2018-09-20 10:08:58,196 basehttp 124 "OPTIONS /emails/ HTTP/1.1" 200 0
INFO 2018-09-20 10:08:58,263 basehttp 124 "PUT /emails/ HTTP/1.1" 200 36
INFO 2018-09-20 10:09:00,619 basehttp 124 "GET /user/ HTTP/1.1" 200 101
WARNING 2018-09-20 10:09:00,667 base 152 Not Found: /browse_histories/
WARNING 2018-09-20 10:09:00,670 basehttp 124 "GET /browse_histories/ HTTP/1.1" 404 3305
INFO 2018-09-20 10:09:01,744 basehttp 124 "PUT /emails/ HTTP/1.1" 200 36
INFO 2018-09-20 10:10:13,111 basehttp 124 "OPTIONS /authorizations/ HTTP/1.1" 200 0
INFO 2018-09-20 10:10:13,148 basehttp 124 "POST /authorizations/ HTTP/1.1" 200 232
INFO 2018-09-20 10:10:13,257 basehttp 124 "GET /user/ HTTP/1.1" 200 101
WARNING 2018-09-20 10:10:13,319 base 152 Not Found: /browse_histories/
WARNING 2018-09-20 10:10:13,321 basehttp 124 "GET /browse_histories/ HTTP/1.1" 404 3305
INFO 2018-09-20 10:10:14,585 basehttp 124 "PUT /emails/ HTTP/1.1" 200 36
INFO 2018-09-20 10:11:28,241 basehttp 124 "OPTIONS /authorizations/ HTTP/1.1" 200 0
INFO 2018-09-20 10:11:28,280 basehttp 124 "POST /authorizations/ HTTP/1.1" 200 232
INFO 2018-09-20 10:11:31,333 basehttp 124 "OPTIONS /user/ HTTP/1.1" 200 0
INFO 2018-09-20 10:11:31,386 basehttp 124 "GET /user/ HTTP/1.1" 200 101
INFO 2018-09-20 10:11:31,400 basehttp 124 "OPTIONS /browse_histories/ HTTP/1.1" 200 0
WARNING 2018-09-20 10:11:31,411 base 152 Not Found: /browse_histories/
WARNING 2018-09-20 10:11:31,412 basehttp 124 "GET /browse_histories/ HTTP/1.1" 404 3305
INFO 2018-09-20 10:11:35,925 basehttp 124 "OPTIONS /emails/ HTTP/1.1" 200 0
INFO 2018-09-20 10:11:35,945 basehttp 124 "PUT /emails/ HTTP/1.1" 200 36
WARNING 2018-09-20 10:12:54,374 base 152 Not Found: /
WARNING 2018-09-20 10:12:54,374 basehttp 124 "GET / HTTP/1.1" 404 3236
WARNING 2018-09-20 10:12:54,445 base 152 Not Found: /favicon.ico
WARNING 2018-09-20 10:12:54,445 basehttp 124 "GET /favicon.ico HTTP/1.1" 404 3287
WARNING 2018-09-20 10:13:25,604 base 152 Not Found: /
WARNING 2018-09-20 10:13:25,605 basehttp 124 "GET / HTTP/1.1" 404 3230
WARNING 2018-09-20 10:13:25,665 base 152 Not Found: /favicon.ico
WARNING 2018-09-20 10:13:25,665 basehttp 124 "GET /favicon.ico HTTP/1.1" 404 3281
INFO 2018-09-20 10:15:03,378 basehttp 124 "OPTIONS /authorizations/ HTTP/1.1" 200 0
INFO 2018-09-20 10:15:03,418 basehttp 124 "POST /authorizations/ HTTP/1.1" 200 232
INFO 2018-09-20 10:15:06,382 basehttp 124 "OPTIONS /user/ HTTP/1.1" 200 0
INFO 2018-09-20 10:15:06,426 basehttp 124 "GET /user/ HTTP/1.1" 200 101
INFO 2018-09-20 10:15:06,483 basehttp 124 "OPTIONS /browse_histories/ HTTP/1.1" 200 0
WARNING 2018-09-20 10:15:06,493 base 152 Not Found: /browse_histories/
WARNING 2018-09-20 10:15:06,494 basehttp 124 "GET /browse_histories/ HTTP/1.1" 404 3305
INFO 2018-09-20 10:15:07,606 basehttp 124 "OPTIONS /emails/ HTTP/1.1" 200 0
INFO 2018-09-20 10:15:07,699 basehttp 124 "PUT /emails/ HTTP/1.1" 200 36
WARNING 2018-09-20 10:18:57,394 base 152 Not Found: /
WARNING 2018-09-20 10:18:57,411 basehttp 124 "GET / HTTP/1.1" 404 3230
WARNING 2018-09-20 10:18:57,619 base 152 Not Found: /favicon.ico
WARNING 2018-09-20 10:18:57,619 basehttp 124 "GET /favicon.ico HTTP/1.1" 404 3281
WARNING 2018-09-20 10:20:30,697 base 152 Not Found: /
WARNING 2018-09-20 10:20:30,698 basehttp 124 "GET / HTTP/1.1" 404 3230
WARNING 2018-09-20 10:20:30,985 base 152 Not Found: /favicon.ico
WARNING 2018-09-20 10:20:30,986 basehttp 124 "GET /favicon.ico HTTP/1.1" 404 3281
INFO 2018-09-20 10:27:57,938 basehttp 124 "OPTIONS /authorizations/ HTTP/1.1" 200 0
INFO 2018-09-20 10:27:57,995 basehttp 124 "POST /authorizations/ HTTP/1.1" 200 232
INFO 2018-09-20 10:28:03,784 basehttp 124 "OPTIONS /user/ HTTP/1.1" 200 0
INFO 2018-09-20 10:28:03,864 basehttp 124 "GET /user/ HTTP/1.1" 200 101
INFO 2018-09-20 10:28:03,880 basehttp 124 "OPTIONS /browse_histories/ HTTP/1.1" 200 0
WARNING 2018-09-20 10:28:03,904 base 152 Not Found: /browse_histories/
WARNING 2018-09-20 10:28:03,905 basehttp 124 "GET /browse_histories/ HTTP/1.1" 404 3305
INFO 2018-09-20 10:28:04,971 basehttp 124 "OPTIONS /emails/ HTTP/1.1" 200 0
INFO 2018-09-20 10:28:05,033 basehttp 124 "PUT /emails/ HTTP/1.1" 200 36
WARNING 2018-09-20 10:30:33,414 base 152 Not Found: /
WARNING 2018-09-20 10:30:33,415 basehttp 124 "GET / HTTP/1.1" 404 3230
WARNING 2018-09-20 10:30:33,777 base 152 Not Found: /favicon.ico
WARNING 2018-09-20 10:30:33,781 basehttp 124 "GET /favicon.ico HTTP/1.1" 404 3281
INFO 2018-09-20 10:30:57,260 basehttp 124 "OPTIONS /authorizations/ HTTP/1.1" 200 0
INFO 2018-09-20 10:30:57,301 basehttp 124 "POST /authorizations/ HTTP/1.1" 200 232
INFO 2018-09-20 10:30:59,087 basehttp 124 "OPTIONS /user/ HTTP/1.1" 200 0
INFO 2018-09-20 10:30:59,162 basehttp 124 "GET /user/ HTTP/1.1" 200 101
INFO 2018-09-20 10:30:59,172 basehttp 124 "OPTIONS /browse_histories/ HTTP/1.1" 200 0
WARNING 2018-09-20 10:30:59,191 base 152 Not Found: /browse_histories/
WARNING 2018-09-20 10:30:59,192 basehttp 124 "GET /browse_histories/ HTTP/1.1" 404 3305
INFO 2018-09-20 10:31:00,273 basehttp 124 "OPTIONS /emails/ HTTP/1.1" 200 0
INFO 2018-09-20 10:31:00,304 basehttp 124 "PUT /emails/ HTTP/1.1" 200 36
INFO 2018-09-20 10:32:45,409 basehttp 124 "GET /user/ HTTP/1.1" 200 101
WARNING 2018-09-20 10:32:45,437 base 152 Not Found: /browse_histories/
WARNING 2018-09-20 10:32:45,438 basehttp 124 "GET /browse_histories/ HTTP/1.1" 404 3305
INFO 2018-09-20 10:32:46,036 basehttp 124 "PUT /emails/ HTTP/1.1" 200 36
INFO 2018-09-20 11:03:54,934 basehttp 124 "GET /usernames/lqlqlq/count/ HTTP/1.1" 200 31
INFO 2018-09-20 11:04:06,986 basehttp 124 "GET /mobiles/15170444038/count/ HTTP/1.1" 200 34
INFO 2018-09-20 11:04:14,407 basehttp 124 "GET /mobiles/15222222222/count/ HTTP/1.1" 200 34
INFO 2018-09-20 11:04:15,313 basehttp 124 "GET /sms_codes/15222222222/ HTTP/1.1" 200 16
INFO 2018-09-20 11:04:15,318 basehttp 124 "GET /mobiles/15222222222/count/ HTTP/1.1" 200 34
INFO 2018-09-20 11:04:21,405 basehttp 124 "OPTIONS /users/ HTTP/1.1" 200 0
INFO 2018-09-20 11:04:21,416 basehttp 124 "GET /usernames/lqlqlq/count/ HTTP/1.1" 200 31
INFO 2018-09-20 11:04:21,423 basehttp 124 "GET /mobiles/15222222222/count/ HTTP/1.1" 200 34
INFO 2018-09-20 11:04:21,466 basehttp 124 "POST /users/ HTTP/1.1" 201 316
INFO 2018-09-20 11:04:23,824 basehttp 124 "OPTIONS /user/ HTTP/1.1" 200 0
INFO 2018-09-20 11:04:23,876 basehttp 124 "GET /user/ HTTP/1.1" 200 83
INFO 2018-09-20 11:04:23,896 basehttp 124 "OPTIONS /browse_histories/ HTTP/1.1" 200 0
WARNING 2018-09-20 11:04:23,910 base 152 Not Found: /browse_histories/
WARNING 2018-09-20 11:04:23,911 basehttp 124 "GET /browse_histories/ HTTP/1.1" 404 3305
INFO 2018-09-20 11:04:39,923 basehttp 124 "OPTIONS /emails/ HTTP/1.1" 200 0
INFO 2018-09-20 11:04:39,983 basehttp 124 "PUT /emails/ HTTP/1.1" 200 36
INFO 2018-09-20 11:04:42,062 basehttp 124 "GET /user/ HTTP/1.1" 200 100
WARNING 2018-09-20 11:04:42,080 base 152 Not Found: /browse_histories/
WARNING 2018-09-20 11:04:42,082 basehttp 124 "GET /browse_histories/ HTTP/1.1" 404 3305
INFO 2018-09-20 11:04:48,381 basehttp 124 "PUT /emails/ HTTP/1.1" 200 36
INFO 2018-09-20 11:05:10,981 basehttp 124 "OPTIONS /authorizations/ HTTP/1.1" 200 0
INFO 2018-09-20 11:05:11,021 basehttp 124 "POST /authorizations/ HTTP/1.1" 200 232
INFO 2018-09-20 11:05:12,985 basehttp 124 "GET /user/ HTTP/1.1" 200 101
WARNING 2018-09-20 11:05:13,027 base 152 Not Found: /browse_histories/
WARNING 2018-09-20 11:05:13,028 basehttp 124 "GET /browse_histories/ HTTP/1.1" 404 3305
INFO 2018-09-20 11:05:13,923 basehttp 124 "PUT /emails/ HTTP/1.1" 200 36
WARNING 2018-09-20 11:09:25,057 base 152 Not Found: /
WARNING 2018-09-20 11:09:25,059 basehttp 124 "GET / HTTP/1.1" 404 3230
WARNING 2018-09-20 11:09:25,337 base 152 Not Found: /favicon.ico
WARNING 2018-09-20 11:09:25,340 basehttp 124 "GET /favicon.ico HTTP/1.1" 404 3281
WARNING 2018-09-20 15:15:26,477 base 152 Not Found: /
WARNING 2018-09-20 15:15:26,479 basehttp 124 "GET / HTTP/1.1" 404 3230
WARNING 2018-09-20 15:15:26,854 base 152 Not Found: /favicon.ico
WARNING 2018-09-20 15:15:26,855 basehttp 124 "GET /favicon.ico HTTP/1.1" 404 3281
INFO 2018-09-20 15:16:56,264 basehttp 124 "OPTIONS /authorizations/ HTTP/1.1" 200 0
INFO 2018-09-20 15:16:56,343 basehttp 124 "POST /authorizations/ HTTP/1.1" 200 232
INFO 2018-09-20 15:16:58,542 basehttp 124 "OPTIONS /user/ HTTP/1.1" 200 0
INFO 2018-09-20 15:16:58,627 basehttp 124 "GET /user/ HTTP/1.1" 200 101
INFO 2018-09-20 15:16:58,646 basehttp 124 "OPTIONS /browse_histories/ HTTP/1.1" 200 0
WARNING 2018-09-20 15:16:58,678 base 152 Not Found: /browse_histories/
WARNING 2018-09-20 15:16:58,679 basehttp 124 "GET /browse_histories/ HTTP/1.1" 404 3475
INFO 2018-09-20 15:17:01,020 basehttp 124 "OPTIONS /emails/ HTTP/1.1" 200 0
INFO 2018-09-20 15:17:01,137 basehttp 124 "PUT /emails/ HTTP/1.1" 200 36
INFO 2018-09-20 15:19:54,368 basehttp 124 "GET /user/ HTTP/1.1" 200 101
WARNING 2018-09-20 15:19:54,434 base 152 Not Found: /browse_histories/
WARNING 2018-09-20 15:19:54,439 basehttp 124 "GET /browse_histories/ HTTP/1.1" 404 3475
INFO 2018-09-20 15:22:21,061 basehttp 124 "GET /user/ HTTP/1.1" 200 101
WARNING 2018-09-20 15:22:21,096 base 152 Not Found: /browse_histories/
WARNING 2018-09-20 15:22:21,097 basehttp 124 "GET /browse_histories/ HTTP/1.1" 404 3475
INFO 2018-09-20 15:22:44,194 basehttp 124 "PUT /emails/ HTTP/1.1" 200 36
INFO 2018-09-20 15:23:10,214 basehttp 124 "GET /emails/verification/?token=eyJpYXQiOjE1Mzc0MjgxNjQsImV4cCI6MTUzNzQyODQ2NCwiYWxnIjoiSFMyNTYifQ.eyJ1c2VyX2lkIjoxLCJlbWFpbCI6IjExMDMxNDc1NzdAcXEuY29tIn0.SKIl5HNOEUn-CobEEweSvNGf5G_lhaodviEwRHSiA9c HTTP/1.1" 200 16
INFO 2018-09-20 15:23:27,222 basehttp 124 "GET /user/ HTTP/1.1" 200 100
WARNING 2018-09-20 15:23:27,284 base 152 Not Found: /browse_histories/
WARNING 2018-09-20 15:23:27,288 basehttp 124 "GET /browse_histories/ HTTP/1.1" 404 3475
INFO 2018-09-20 15:29:19,758 basehttp 124 "GET /usernames/zxwzxw/count/ HTTP/1.1" 200 31
INFO 2018-09-20 15:29:43,140 basehttp 124 "GET /mobiles/15000000000/count/ HTTP/1.1" 200 34
INFO 2018-09-20 15:29:43,285 basehttp 124 "GET /sms_codes/15000000000/ HTTP/1.1" 200 16
INFO 2018-09-20 15:29:43,291 basehttp 124 "GET /mobiles/15000000000/count/ HTTP/1.1" 200 34
INFO 2018-09-20 15:29:52,418 basehttp 124 "OPTIONS /users/ HTTP/1.1" 200 0
INFO 2018-09-20 15:29:52,443 basehttp 124 "GET /usernames/zxwzxw/count/ HTTP/1.1" 200 31
INFO 2018-09-20 15:29:52,445 basehttp 124 "GET /mobiles/15000000000/count/ HTTP/1.1" 200 34
INFO 2018-09-20 15:29:52,519 basehttp 124 "POST /users/ HTTP/1.1" 201 316
INFO 2018-09-20 15:29:54,725 basehttp 124 "OPTIONS /user/ HTTP/1.1" 200 0
INFO 2018-09-20 15:29:54,794 basehttp 124 "GET /user/ HTTP/1.1" 200 83
INFO 2018-09-20 15:29:54,817 basehttp 124 "OPTIONS /browse_histories/ HTTP/1.1" 200 0
WARNING 2018-09-20 15:29:54,836 base 152 Not Found: /browse_histories/
WARNING 2018-09-20 15:29:54,838 basehttp 124 "GET /browse_histories/ HTTP/1.1" 404 3475
INFO 2018-09-20 15:30:15,097 basehttp 124 "OPTIONS /emails/ HTTP/1.1" 200 0
INFO 2018-09-20 15:30:15,203 basehttp 124 "PUT /emails/ HTTP/1.1" 200 36
INFO 2018-09-20 15:30:17,365 basehttp 124 "GET /user/ HTTP/1.1" 200 100
WARNING 2018-09-20 15:30:17,425 base 152 Not Found: /browse_histories/
WARNING 2018-09-20 15:30:17,430 basehttp 124 "GET /browse_histories/ HTTP/1.1" 404 3475
INFO 2018-09-20 15:30:18,949 basehttp 124 "PUT /emails/ HTTP/1.1" 200 36
INFO 2018-09-20 15:30:52,444 basehttp 124 "OPTIONS /authorizations/ HTTP/1.1" 200 0
INFO 2018-09-20 15:30:52,489 basehttp 124 "POST /authorizations/ HTTP/1.1" 200 232
INFO 2018-09-20 15:30:56,887 basehttp 124 "GET /user/ HTTP/1.1" 200 101
WARNING 2018-09-20 15:30:56,939 base 152 Not Found: /browse_histories/
WARNING 2018-09-20 15:30:56,940 basehttp 124 "GET /browse_histories/ HTTP/1.1" 404 3475
INFO 2018-09-20 15:31:12,239 basehttp 124 "POST /authorizations/ HTTP/1.1" 200 229
INFO 2018-09-20 15:31:14,359 basehttp 124 "GET /user/ HTTP/1.1" 200 100
WARNING 2018-09-20 15:31:14,394 base 152 Not Found: /browse_histories/
WARNING 2018-09-20 15:31:14,395 basehttp 124 "GET /browse_histories/ HTTP/1.1" 404 3475
INFO 2018-09-20 15:31:17,636 basehttp 124 "PUT /emails/ HTTP/1.1" 200 36
INFO 2018-09-20 15:35:23,537 basehttp 124 "POST /authorizations/ HTTP/1.1" 200 232
INFO 2018-09-20 15:35:25,931 basehttp 124 "GET /user/ HTTP/1.1" 200 100
WARNING 2018-09-20 15:35:25,977 base 152 Not Found: /browse_histories/
WARNING 2018-09-20 15:35:25,978 basehttp 124 "GET /browse_histories/ HTTP/1.1" 404 3475
INFO 2018-09-20 15:35:28,740 basehttp 124 "GET /user/ HTTP/1.1" 200 100
WARNING 2018-09-20 15:35:28,785 base 152 Not Found: /browse_histories/
WARNING 2018-09-20 15:35:28,785 basehttp 124 "GET /browse_histories/ HTTP/1.1" 404 3475
INFO 2018-09-20 15:37:22,316 basehttp 124 "POST /authorizations/ HTTP/1.1" 200 229
INFO 2018-09-20 15:37:24,834 basehttp 124 "GET /user/ HTTP/1.1" 200 100
WARNING 2018-09-20 15:37:24,891 base 152 Not Found: /browse_histories/
WARNING 2018-09-20 15:37:24,892 basehttp 124 "GET /browse_histories/ HTTP/1.1" 404 3475
INFO 2018-09-20 15:37:25,924 basehttp 124 "PUT /emails/ HTTP/1.1" 200 36
INFO 2018-09-20 15:37:48,366 basehttp 124 "GET /user/ HTTP/1.1" 200 100
WARNING 2018-09-20 15:37:48,417 base 152 Not Found: /browse_histories/
WARNING 2018-09-20 15:37:48,418 basehttp 124 "GET /browse_histories/ HTTP/1.1" 404 3475
INFO 2018-09-20 15:37:48,973 basehttp 124 "PUT /emails/ HTTP/1.1" 200 36
INFO 2018-09-20 15:39:04,160 basehttp 124 "GET /user/ HTTP/1.1" 200 100
WARNING 2018-09-20 15:39:04,187 base 152 Not Found: /browse_histories/
WARNING 2018-09-20 15:39:04,188 basehttp 124 "GET /browse_histories/ HTTP/1.1" 404 3475
INFO 2018-09-20 15:39:04,931 basehttp 124 "PUT /emails/ HTTP/1.1" 200 36
INFO 2018-09-20 15:39:31,802 basehttp 124 "POST /authorizations/ HTTP/1.1" 200 229
INFO 2018-09-20 15:39:34,130 basehttp 124 "GET /user/ HTTP/1.1" 200 100
WARNING 2018-09-20 15:39:34,185 base 152 Not Found: /browse_histories/
WARNING 2018-09-20 15:39:34,186 basehttp 124 "GET /browse_histories/ HTTP/1.1" 404 3475
INFO 2018-09-20 15:39:35,469 basehttp 124 "PUT /emails/ HTTP/1.1" 200 36
INFO 2018-09-20 15:39:49,756 basehttp 124 "POST /authorizations/ HTTP/1.1" 200 232
INFO 2018-09-20 15:39:51,751 basehttp 124 "GET /user/ HTTP/1.1" 200 101
WARNING 2018-09-20 15:39:51,807 base 152 Not Found: /browse_histories/
WARNING 2018-09-20 15:39:51,809 basehttp 124 "GET /browse_histories/ HTTP/1.1" 404 3475
INFO 2018-09-20 15:39:53,305 basehttp 124 "GET /user/ HTTP/1.1" 200 101
WARNING 2018-09-20 15:39:53,334 base 152 Not Found: /browse_histories/
WARNING 2018-09-20 15:39:53,335 basehttp 124 "GET /browse_histories/ HTTP/1.1" 404 3475
INFO 2018-09-20 15:39:54,028 basehttp 124 "PUT /emails/ HTTP/1.1" 200 36
INFO 2018-09-20 19:54:53,836 basehttp 124 "OPTIONS /user/ HTTP/1.1" 200 0
WARNING 2018-09-20 19:54:53,883 basehttp 124 "GET /user/ HTTP/1.1" 401 38
INFO 2018-09-20 19:55:14,741 basehttp 124 "OPTIONS /authorizations/ HTTP/1.1" 200 0
WARNING 2018-09-20 19:55:14,781 basehttp 124 "POST /authorizations/ HTTP/1.1" 400 67
INFO 2018-09-20 19:55:22,785 basehttp 124 "POST /authorizations/ HTTP/1.1" 200 229
INFO 2018-09-20 19:55:22,884 basehttp 124 "GET /user/ HTTP/1.1" 200 100
INFO 2018-09-20 19:55:22,910 basehttp 124 "OPTIONS /browse_histories/ HTTP/1.1" 200 0
WARNING 2018-09-20 19:55:22,928 base 152 Not Found: /browse_histories/
WARNING 2018-09-20 19:55:22,929 basehttp 124 "GET /browse_histories/ HTTP/1.1" 404 3475
INFO 2018-09-20 19:55:26,229 basehttp 124 "GET /user/ HTTP/1.1" 200 100
WARNING 2018-09-20 19:55:26,247 base 152 Not Found: /browse_histories/
WARNING 2018-09-20 19:55:26,248 basehttp 124 "GET /browse_histories/ HTTP/1.1" 404 3475
INFO 2018-09-20 19:55:27,041 basehttp 124 "OPTIONS /emails/ HTTP/1.1" 200 0
INFO 2018-09-20 19:55:27,105 basehttp 124 "PUT /emails/ HTTP/1.1" 200 36
INFO 2018-09-20 19:55:29,176 basehttp 124 "GET /user/ HTTP/1.1" 200 100
WARNING 2018-09-20 19:55:29,201 base 152 Not Found: /browse_histories/
WARNING 2018-09-20 19:55:29,202 basehttp 124 "GET /browse_histories/ HTTP/1.1" 404 3475
INFO 2018-09-20 19:59:42,776 basehttp 124 "OPTIONS /authorizations/ HTTP/1.1" 200 0
INFO 2018-09-20 19:59:42,818 basehttp 124 "POST /authorizations/ HTTP/1.1" 200 229
INFO 2018-09-20 19:59:50,533 basehttp 124 "OPTIONS /user/ HTTP/1.1" 200 0
INFO 2018-09-20 19:59:50,613 basehttp 124 "GET /user/ HTTP/1.1" 200 100
INFO 2018-09-20 19:59:50,630 basehttp 124 "OPTIONS /browse_histories/ HTTP/1.1" 200 0
WARNING 2018-09-20 19:59:50,647 base 152 Not Found: /browse_histories/
WARNING 2018-09-20 19:59:50,648 basehttp 124 "GET /browse_histories/ HTTP/1.1" 404 3475
INFO 2018-09-20 20:00:17,367 basehttp 124 "POST /authorizations/ HTTP/1.1" 200 229
INFO 2018-09-20 20:00:20,253 basehttp 124 "GET /user/ HTTP/1.1" 200 100
WARNING 2018-09-20 20:00:20,299 base 152 Not Found: /browse_histories/
WARNING 2018-09-20 20:00:20,300 basehttp 124 "GET /browse_histories/ HTTP/1.1" 404 3475
INFO 2018-09-20 20:00:22,511 basehttp 124 "OPTIONS /emails/ HTTP/1.1" 200 0
INFO 2018-09-20 20:00:22,533 basehttp 124 "PUT /emails/ HTTP/1.1" 200 36
WARNING 2018-09-20 20:04:33,681 tasks 30 发送验证码短信[失败][ mobile: 15888888888 ]
WARNING 2018-09-21 19:51:58,123 base 152 Not Found: /
WARNING 2018-09-21 19:51:58,124 basehttp 124 "GET / HTTP/1.1" 404 3507
WARNING 2018-09-21 19:51:58,335 base 152 Not Found: /favicon.ico
WARNING 2018-09-21 19:51:58,339 basehttp 124 "GET /favicon.ico HTTP/1.1" 404 3558
WARNING 2018-09-21 19:52:54,363 base 152 Not Found: /
WARNING 2018-09-21 19:52:54,364 basehttp 124 "GET / HTTP/1.1" 404 3507
WARNING 2018-09-21 19:53:06,037 base 152 Not Found: /areas/
WARNING 2018-09-21 19:53:06,038 basehttp 124 "GET /areas/ HTTP/1.1" 404 3778
INFO 2018-09-21 19:53:32,272 basehttp 124 "GET /areas/ HTTP/1.1" 200 5018
INFO 2018-09-21 19:56:37,560 basehttp 124 "GET /areas/ HTTP/1.1" 200 8261
INFO 2018-09-21 20:44:59,952 basehttp 124 "GET /areas/ HTTP/1.1" 200 8261
WARNING 2018-09-21 20:45:17,053 base 152 Not Found: /
WARNING 2018-09-21 20:45:17,058 basehttp 124 "GET / HTTP/1.1" 404 3730
WARNING 2018-09-21 20:45:17,426 base 152 Not Found: /favicon.ico
WARNING 2018-09-21 20:45:17,427 basehttp 124 "GET /favicon.ico HTTP/1.1" 404 3781
INFO 2018-09-21 20:45:23,640 basehttp 124 "GET /areas/ HTTP/1.1" 200 8261
